Workbook

Sheet DASHBOARD
A1: DASHBOARD DE COMBUSTIBLE - UE 0725 AMAZONAS
A3: REPORTE 2025 | F3: REPORTE DE COMBUSTIBLE DE FUAS INGRESADAS - 2026
A4: COMBUSTIBLE | B4: GALONES | C4: SOLES S/. | F4: MES | G4: TRASLADOS | H4: GAL PET | I4: GAL GAS | J4: TOT GAL | K4: S/. PET | L4: S/. GAS | M4: TOT S/.
A5: PETROLEO | B5: 8761 | C5: 164087.8 | F5: ENE | G5: =IFERROR(COUNTA('ENERO 2026'!A6:A119),0) -> 94 | H5: =IFERROR(SUMIFS('ENERO 2026'!M6:M119,'ENERO 2026'!K6:K119,"PETROLEO"),0) -> 630.55 | I5: =IFERROR(SUMIFS('ENERO 2026'!M6:M119,'ENERO 2026'!K6:K119,"GASOLINA"),0) -> 36 | J5: =H5+I5 -> 666.55 | K5: =IFERROR(SUMIFS('ENERO 2026'!N6:N119,'ENERO 2026'!K6:K119,"PETROLEO"),0) -> 11876.468 | L5: =IFERROR(SUMIFS('ENERO 2026'!N6:N119,'ENERO 2026'!K6:K119,"GASOLINA"),0) -> 646.2 | M5: =K5+L5 -> 12522.667
A6: GASOLINA | B6: 1274 | C6: 22870.2 | F6: FEB | G6: =IFERROR(COUNTA('FEBRERO 2026'!A6:A124),0) -> 99 | H6: =IFERROR(SUMIFS('FEBRERO 2026'!M6:M124,'FEBRERO 2026'!K6:K124,"PETROLEO"),0) -> 676.09 | I6: =IFERROR(SUMIFS('FEBRERO 2026'!M6:M124,'FEBRERO 2026'!K6:K124,"GASOLINA"),0) -> 138 | J6: =H6+I6 -> 814.09 | K6: =IFERROR(SUMIFS('FEBRERO 2026'!N6:N124,'FEBRERO 2026'!K6:K124,"PETROLEO"),0) -> 12648.233 | L6: =IFERROR(SUMIFS('FEBRERO 2026'!N6:N124,'FEBRERO 2026'!K6:K124,"GASOLINA"),0) -> 2477.1 | M6: =K6+L6 -> 15125.333
A7: TOTAL | B7: 10035 | C7: 186958 | F7: MAR | G7: =IFERROR(COUNTA('MARZO 2026'!A6:A119),0) -> 94 | H7: =IFERROR(SUMIFS('MARZO 2026'!M6:M119,'MARZO 2026'!K6:K119,"PETROLEO"),0) -> 330.16 | I7: =IFERROR(SUMIFS('MARZO 2026'!M6:M119,'MARZO 2026'!K6:K119,"GASOLINA"),0) -> 55 | J7: =H7+I7 -> 385.16 | K7: =IFERROR(SUMIFS('MARZO 2026'!N6:N119,'MARZO 2026'!K6:K119,"PETROLEO"),0) -> 6263.46 | L7: =IFERROR(SUMIFS('MARZO 2026'!N6:N119,'MARZO 2026'!K6:K119,"GASOLINA"),0) -> 987.25 | M7: =K7+L7 -> 7250.71
F8: ABR | G8: =IFERROR(COUNTA('ABRIL 2026'!A6:A119),0) -> 94 | H8: =IFERROR(SUMIFS('ABRIL 2026'!M6:M119,'ABRIL 2026'!K6:K119,"PETROLEO"),0) -> 0 | I8: =IFERROR(SUMIFS('ABRIL 2026'!M6:M119,'ABRIL 2026'!K6:K119,"GASOLINA"),0) -> 0 | J8: =H8+I8 -> 0 | K8: =IFERROR(SUMIFS('ABRIL 2026'!N6:N119,'ABRIL 2026'!K6:K119,"PETROLEO"),0) -> 0 | L8: =IFERROR(SUMIFS('ABRIL 2026'!N6:N119,'ABRIL 2026'!K6:K119,"GASOLINA"),0) -> 0 | M8: =K8+L8 -> 0
F9: MAY | G9: =IFERROR(COUNTA('MAYO 2026'!A6:A110),0) -> 0 | H9: =IFERROR(SUMIFS('MAYO 2026'!M6:M110,'MAYO 2026'!K6:K110,"PETROLEO"),0) -> 0 | I9: =IFERROR(SUMIFS('MAYO 2026'!M6:M110,'MAYO 2026'!K6:K110,"GASOLINA"),0) -> 0 | J9: =H9+I9 -> 0 | K9: =IFERROR(SUMIFS('MAYO 2026'!N6:N110,'MAYO 2026'!K6:K110,"PETROLEO"),0) -> 0 | L9: =IFERROR(SUMIFS('MAYO 2026'!N6:N110,'MAYO 2026'!K6:K110,"GASOLINA"),0) -> 0 | M9: =K9+L9 -> 0
F10: JUN | G10: =IFERROR(COUNTA('JUNIO 2026'!A6:A110),0) -> 0 | H10: =IFERROR(SUMIFS('JUNIO 2026'!M6:M110,'JUNIO 2026'!K6:K110,"PETROLEO"),0) -> 0 | I10: =IFERROR(SUMIFS('JUNIO 2026'!M6:M110,'JUNIO 2026'!K6:K110,"GASOLINA"),0) -> 0 | J10: =H10+I10 -> 0 | K10: =IFERROR(SUMIFS('JUNIO 2026'!N6:N110,'JUNIO 2026'!K6:K110,"PETROLEO"),0) -> 0 | L10: =IFERROR(SUMIFS('JUNIO 2026'!N6:N110,'JUNIO 2026'!K6:K110,"GASOLINA"),0) -> 0 | M10: =K10+L10 -> 0
A11: REPORTE 2026 | F11: JUL | G11: =IFERROR(COUNTA('JULIO 2026'!A6:A110),0) -> 0 | H11: =IFERROR(SUMIFS('JULIO 2026'!M6:M110,'JULIO 2026'!K6:K110,"PETROLEO"),0) -> 0 | I11: =IFERROR(SUMIFS('JULIO 2026'!M6:M110,'JULIO 2026'!K6:K110,"GASOLINA"),0) -> 0 | J11: =H11+I11 -> 0 | K11: =IFERROR(SUMIFS('JULIO 2026'!N6:N110,'JULIO 2026'!K6:K110,"PETROLEO"),0) -> 0 | L11: =IFERROR(SUMIFS('JULIO 2026'!N6:N110,'JULIO 2026'!K6:K110,"GASOLINA"),0) -> 0 | M11: =K11+L11 -> 0
A12: COMBUSTIBLE | B12: GALONES | C12: SOLES S/. | F12: AGO | G12: =IFERROR(COUNTA('AGOSTO 2026'!A6:A110),0) -> 0 | H12: =IFERROR(SUMIFS('AGOSTO 2026'!M6:M110,'AGOSTO 2026'!K6:K110,"PETROLEO"),0) -> 0 | I12: =IFERROR(SUMIFS('AGOSTO 2026'!M6:M110,'AGOSTO 2026'!K6:K110,"GASOLINA"),0) -> 0 | J12: =H12+I12 -> 0 | K12: =IFERROR(SUMIFS('AGOSTO 2026'!N6:N110,'AGOSTO 2026'!K6:K110,"PETROLEO"),0) -> 0 | L12: =IFERROR(SUMIFS('AGOSTO 2026'!N6:N110,'AGOSTO 2026'!K6:K110,"GASOLINA"),0) -> 0 | M12: =K12+L12 -> 0
A13: PETROLEO | B13: =SUM(H5:H16) -> 1636.8 | C13: =SUM(K5:K16) -> 30788.16 | F13: SET | G13: =IFERROR(COUNTA('SETIEMBRE 2026'!A6:A110),0) -> 0 | H13: =IFERROR(SUMIFS('SETIEMBRE 2026'!M6:M110,'SETIEMBRE 2026'!K6:K110,"PETROLEO"),0) -> 0 | I13: =IFERROR(SUMIFS('SETIEMBRE 2026'!M6:M110,'SETIEMBRE 2026'!K6:K110,"GASOLINA"),0) -> 0 | J13: =H13+I13 -> 0 | K13: =IFERROR(SUMIFS('SETIEMBRE 2026'!N6:N110,'SETIEMBRE 2026'!K6:K110,"PETROLEO"),0) -> 0 | L13: =IFERROR(SUMIFS('SETIEMBRE 2026'!N6:N110,'SETIEMBRE 2026'!K6:K110,"GASOLINA"),0) -> 0 | M13: =K13+L13 -> 0
A14: GASOLINA | B14: =SUM(I5:I16) -> 229 | C14: =SUM(L5:L16) -> 4110.55 | F14: OCT | G14: =IFERROR(COUNTA('OCTUBRE 2026'!A6:A110),0) -> 0 | H14: =IFERROR(SUMIFS('OCTUBRE 2026'!M6:M110,'OCTUBRE 2026'!K6:K110,"PETROLEO"),0) -> 0 | I14: =IFERROR(SUMIFS('OCTUBRE 2026'!M6:M110,'OCTUBRE 2026'!K6:K110,"GASOLINA"),0) -> 0 | J14: =H14+I14 -> 0 | K14: =IFERROR(SUMIFS('OCTUBRE 2026'!N6:N110,'OCTUBRE 2026'!K6:K110,"PETROLEO"),0) -> 0 | L14: =IFERROR(SUMIFS('OCTUBRE 2026'!N6:N110,'OCTUBRE 2026'!K6:K110,"GASOLINA"),0) -> 0 | M14: =K14+L14 -> 0
A15: TOTAL | B15: =B13+B14 -> 1865.8 | C15: =C13+C14 -> 34898.71 | F15: NOV | G15: =IFERROR(COUNTA('NOVIEMBRE 2026'!A6:A110),0) -> 0 | H15: =IFERROR(SUMIFS('NOVIEMBRE 2026'!M6:M110,'NOVIEMBRE 2026'!K6:K110,"PETROLEO"),0) -> 0 | I15: =IFERROR(SUMIFS('NOVIEMBRE 2026'!M6:M110,'NOVIEMBRE 2026'!K6:K110,"GASOLINA"),0) -> 0 | J15: =H15+I15 -> 0 | K15: =IFERROR(SUMIFS('NOVIEMBRE 2026'!N6:N110,'NOVIEMBRE 2026'!K6:K110,"PETROLEO"),0) -> 0 | L15: =IFERROR(SUMIFS('NOVIEMBRE 2026'!N6:N110,'NOVIEMBRE 2026'!K6:K110,"GASOLINA"),0) -> 0 | M15: =K15+L15 -> 0
F16: DIC | G16: =IFERROR(COUNTA('DICIEMBRE 2026'!A6:A110),0) -> 0 | H16: =IFERROR(SUMIFS('DICIEMBRE 2026'!M6:M110,'DICIEMBRE 2026'!K6:K110,"PETROLEO"),0) -> 0 | I16: =IFERROR(SUMIFS('DICIEMBRE 2026'!M6:M110,'DICIEMBRE 2026'!K6:K110,"GASOLINA"),0) -> 0 | J16: =H16+I16 -> 0 | K16: =IFERROR(SUMIFS('DICIEMBRE 2026'!N6:N110,'DICIEMBRE 2026'!K6:K110,"PETROLEO"),0) -> 0 | L16: =IFERROR(SUMIFS('DICIEMBRE 2026'!N6:N110,'DICIEMBRE 2026'!K6:K110,"GASOLINA"),0) -> 0 | M16: =K16+L16 -> 0
F17: TOTAL | G17: =SUM(G5:G16) -> 381 | H17: =SUM(H5:H16) -> 1636.8 | I17: =SUM(I5:I16) -> 229 | J17: =SUM(J5:J16) -> 1865.8 | K17: =SUM(K5:K16) -> 30788.16 | L17: =SUM(L5:L16) -> 4110.55 | M17: =SUM(M5:M16) -> 34898.71
A20: ⛽ PETROLEO - COMBUSTIBLE ACUMULADO 2026 POR IPRESS
A21: N° | B21: IPRESS | C21: MICRORED | D21: GALONES PETROLEO | E21: SOLES S/. PETROLEO
A22: 1 | B22: Camporredondo | C22: CAMPORREDONDO | D22: =IFERROR(SUMIF(_CALCULO!$A$2:$A$397,"CAMPORREDONDO",_CALCULO!$C$2:$C$397),0) -> 40 | E22: =IFERROR(SUMIF(_CALCULO!$A$2:$A$397,"CAMPORREDONDO",_CALCULO!$D$2:$D$397),0) -> 727.2
A23: 2 | B23: Chuquibamba | C23: LEIMEBAMBA | D23: =IFERROR(SUMIF(_CALCULO!$A$2:$A$397,"CHUQUIBAMBA",_CALCULO!$C$2:$C$397),0) -> 15 | E23: =IFERROR(SUMIF(_CALCULO!$A$2:$A$397,"CHUQUIBAMBA",_CALCULO!$D$2:$D$397),0) -> 272.7
A24: 3 | B24: Cococho | C24: CAMPORREDONDO | D24: =IFERROR(SUMIF(_CALCULO!$A$2:$A$397,"COCOCHO",_CALCULO!$C$2:$C$397),0) -> 62 | E24: =IFERROR(SUMIF(_CALCULO!$A$2:$A$397,"COCOCHO",_CALCULO!$D$2:$D$397),0) -> 1127.16
A25: 4 | B25: Colcamar | C25: CHACHAPOYAS | D25: =IFERROR(SUMIF(_CALCULO!$A$2:$A$397,"COLCAMAR",_CALCULO!$C$2:$C$397),0) -> 28 | E25: =IFERROR(SUMIF(_CALCULO!$A$2:$A$397,"COLCAMAR",_CALCULO!$D$2:$D$397),0) -> 509.04
A26: 5 | B26: Collonce | C26: COLLONCE | D26: =IFERROR(SUMIF(_CALCULO!$A$2:$A$397,"COLLONCE",_CALCULO!$C$2:$C$397),0) -> 100 | E26: =IFERROR(SUMIF(_CALCULO!$A$2:$A$397,"COLLONCE",_CALCULO!$D$2:$D$397),0) -> 1818
A27: 6 | B27: Duraznopampa | C27: YERBABUENA | D27: =IFERROR(SUMIF(_CALCULO!$A$2:$A$397,"DURAZNOPAMPA",_CALCULO!$C$2:$C$397),0) -> 7 | E27: =IFERROR(SUMIF(_CALCULO!$A$2:$A$397,"DURAZNOPAMPA",_CALCULO!$D$2:$D$397),0) -> 127.26
A28: 7 | B28: Huambo | C28: HUAMBO | D28: =IFERROR(SUMIF(_CALCULO!$A$2:$A$397,"HUAMBO",_CALCULO!$C$2:$C$397),0) -> 45 | E28: =IFERROR(SUMIF(_CALCULO!$A$2:$A$397,"HUAMBO",_CALCULO!$D$2:$D$397),0) -> 911.25
A29: 8 | B29: Jalca Grande | C29: YERBABUENA | D29: =IFERROR(SUMIF(_CALCULO!$A$2:$A$397,"JALCA GRANDE",_CALCULO!$C$2:$C$397),0) -> 49 | E29: =IFERROR(SUMIF(_CALCULO!$A$2:$A$397,"JALCA GRANDE",_CALCULO!$D$2:$D$397),0) -> 890.82
A30: 9 | B30: Jumbilla | C30: JUMBILLA | D30: =IFERROR(SUMIF(_CALCULO!$A$2:$A$397,"JUMBILLA",_CALCULO!$C$2:$C$397),0) -> 34 | E30: =IFERROR(SUMIF(_CALCULO!$A$2:$A$397,"JUMBILLA",_CALCULO!$D$2:$D$397),0) -> 618.12
A31: 10 | B31: Lamud | C31: LAMUD | D31: =IFERROR(SUMIF(_CALCULO!$A$2:$A$397,"LAMUD",_CALCULO!$C$2:$C$397),0) -> 52 | E31: =IFERROR(SUMIF(_CALCULO!$A$2:$A$397,"LAMUD",_CALCULO!$D$2:$D$397),0) -> 945.36
A32: 11 | B32: Leymebamba | C32: LEIMEBAMBA | D32: =IFERROR(SUMIF(_CALCULO!$A$2:$A$397,"LEYMEBAMBA",_CALCULO!$C$2:$C$397),0) -> 36 | E32: =IFERROR(SUMIF(_CALCULO!$A$2:$A$397,"LEYMEBAMBA",_CALCULO!$D$2:$D$397),0) -> 654.48
A33: 12 | B33: Luya | C33: LUYA | D33: =IFERROR(SUMIF(_CALCULO!$A$2:$A$397,"LUYA",_CALCULO!$C$2:$C$397),0) -> 28 | E33: =IFERROR(SUMIF(_CALCULO!$A$2:$A$397,"LUYA",_CALCULO!$D$2:$D$397),0) -> 509.04
A34: 13 | B34: Maria | C34: MARIA | D34: =IFERROR(SUMIF(_CALCULO!$A$2:$A$397,"MARIA",_CALCULO!$C$2:$C$397),0) -> 48 | E34: =IFERROR(SUMIF(_CALCULO!$A$2:$A$397,"MARIA",_CALCULO!$D$2:$D$397),0) -> 872.64
A35: 14 | B35: Maria Auxiliadora | C35: HOSPITAL MARIA AUXILIADORA | D35: =IFERROR(SUMIF(_CALCULO!$A$2:$A$397,"MARIA AUXILIADORA",_CALCULO!$C$2:$C$397),0) -> 381.8 | E35: =IFERROR(SUMIF(_CALCULO!$A$2:$A$397,"MARIA AUXILIADORA",_CALCULO!$D$2:$D$397),0) -> 7710.75
A36: 15 | B36: Mariscal Benavides | C36: LONGAR | D36: =IFERROR(SUMIF(_CALCULO!$A$2:$A$397,"MARISCAL BENAVIDES",_CALCULO!$C$2:$C$397),0) -> 0 | E36: =IFERROR(SUMIF(_CALCULO!$A$2:$A$397,"MARISCAL BENAVIDES",_CALCULO!$D$2:$D$397),0) -> 0
A37: 16 | B37: Nuevo Chirimoto | C37: NUEVO CHIRIMOTO | D37: =IFERROR(SUMIF(_CALCULO!$A$2:$A$397,"NUEVO CHIRIMOTO",_CALCULO!$C$2:$C$397),0) -> 0 | E37: =IFERROR(SUMIF(_CALCULO!$A$2:$A$397,"NUEVO CHIRIMOTO",_CALCULO!$D$2:$D$397),0) -> 0
A38: 17 | B38: Ocalli | C38: OCALLI | D38: =IFERROR(SUMIF(_CALCULO!$A$2:$A$397,"OCALLI",_CALCULO!$C$2:$C$397),0) -> 128 | E38: =IFERROR(SUMIF(_CALCULO!$A$2:$A$397,"OCALLI",_CALCULO!$D$2:$D$397),0) -> 2327.04
A39: 18 | B39: Omia | C39: OMIA | D39: =IFERROR(SUMIF(_CALCULO!$A$2:$A$397,"OMIA",_CALCULO!$C$2:$C$397),0) -> 46 | E39: =IFERROR(SUMIF(_CALCULO!$A$2:$A$397,"OMIA",_CALCULO!$D$2:$D$397),0) -> 931.5
A40: 19 | B40: Pedro Ruiz Gallo | C40: PEDRO RUIZ GALLO | D40: =IFERROR(SUMIF(_CALCULO!$A$2:$A$397,"PEDRO RUIZ GALLO",_CALCULO!$C$2:$C$397),0) -> 116 | E40: =IFERROR(SUMIF(_CALCULO!$A$2:$A$397,"PEDRO RUIZ GALLO",_CALCULO!$D$2:$D$397),0) -> 2107.5
A41: 20 | B41: Pomacochas | C41: POMACOCHAS | D41: =IFERROR(SUMIF(_CALCULO!$A$2:$A$397,"POMACOCHAS",_CALCULO!$C$2:$C$397),0) -> 162 | E41: =IFERROR(SUMIF(_CALCULO!$A$2:$A$397,"POMACOCHAS",_CALCULO!$D$2:$D$397),0) -> 2945.16
A42: 21 | B42: San Juan De Ocumal | C42: COLLONCE | D42: =IFERROR(SUMIF(_CALCULO!$A$2:$A$397,"SAN JUAN DE OCUMAL",_CALCULO!$C$2:$C$397),0) -> 20 | E42: =IFERROR(SUMIF(_CALCULO!$A$2:$A$397,"SAN JUAN DE OCUMAL",_CALCULO!$D$2:$D$397),0) -> 363.6
A43: 22 | B43: San Salvador | C43: SANTO TOMAS | D43: =IFERROR(SUMIF(_CALCULO!$A$2:$A$397,"SAN SALVADOR",_CALCULO!$C$2:$C$397),0) -> 10 | E43: =IFERROR(SUMIF(_CALCULO!$A$2:$A$397,"SAN SALVADOR",_CALCULO!$D$2:$D$397),0) -> 181.8
...

Sheet CONDUCTORES
A1: CATALOGO DE CONDUCTORES - UE 0725 AMAZONAS
A2: DNI | B2: APELLIDOS Y NOMBRES | C2: N LICENCIA | D2: CATEGORIA | E2: MODELO VEHICULO | F2: PLACA | G2: TIPO COMBUSTIBLE | H2: C.S ASIGNADO
A3: 44333747 | B3: GUEVARA VASQUEZ GREIMER MELGAR | C3: Q 44333747 | D3: A II B | E3: HILUX 4X4 TIPO II | F3: EUE 651 | G3: PETROLEO | H3: CAMPORREDONDO
A4: 33432847 | B4: BUELOT VISALOT CARLO MAGNO | C4: W33432847 | D4: ALLB | E4: TIPO I | F4: EUD 634 | G4: PETROLEO | H4: COLCAMAR
A5: 73602628 | B5: SAUCEDO LOPEZ ELDIN NOLASCO | C5: Q73602628 | D5: A2B | E5: TIPO II | F5: EUH699 | G5: PETROLEO | H5: COLLONCE
A6: 44426318 | B6: ABANTO VALDIVIA HANS MIKKEL | C6: W44426318 | D6: A LLL C | E6: TOYOTA HILUX | F6: EUH 640 | G6: PETROLEO | H6: CHUQUIBAMBA
A7: 9990954 | B7: TRIGOSO TAFUR JOSE GILBER | C7: Q09990954 | D7: A LLL C | E7: NISSAN URBAN | F7: EUH 421 | G7: PETROLEO | H7: MARIA AUXILIADORA
A8: 42333513 | B8: PORTOCARRERO PELAEZ MIGUEL ANTONIO | C8: W42333513 | D8: A3C | E8: NISSAN URVAN | F8: EUH-421 | G8: PETROLEO | H8: MARIA AUXILIADORA
A9: 41785950 | B9: SERNAQUE PELAEZ WILMER | C9: W417859506 | D9: A2B | E9: TIPO II | F9: EUH-421 | G9: PETROLEO | H9: MARIA AUXILIADORA
A10: 33402316 | B10: ROJAS ALVARADO BENJAMIN | C10: W33502316 | D10: A LL B | E10: NISSAN URVAN | F10: 421 EUH | G10: PETROLEO | H10: MARIA AUXILIADORA
A11: 40083507 | B11: LOPEZ HOYOS MIGUEL ANGEL | C11: W40083507 | D11: AIIIC | E11: HILUX | F11: EUH-698 | G11: PETROLEO | H11: HUAMBO
A12: 44894499 | B12: LEIVA LARA JUNIOR | C12: W44894499 | D12: A LL. B | E12: TRANSPORTER 2014 | F12: EUC 959 | G12: PETROLEO | H12: JALCA GRANDE
A13: 33734466 | B13: BRICENO OXOLON MANUEL | C13: 33734466 | D13: AIIIC | E13: TRANSPORTER | F13: EUC976 | G13: PETROLEO | H13: JUMBILLA
... A33: 70790222 | B33: VILLA GONGORA RODVIN LUIS | C33: W70790222 | D33: AII-B | E33: TOYOTA HILUX 4X4 T-II | F33: EUD-684 | G33: PETROLEO | H33: TOTORA
A34: 33725999 | B34: CHICANA VALLE JAIME | D34: A 2B | E34: BOXER | F34: EGU 916 | G34: PETROLEO | H34: YAMBRASBAMBA
A35: 40051255 | B35: SANCHEZ CAJO VICENTE | C35: C40051255 | D35: A2B | E35: TOYOTA HIACE | F35: EGL-296 | G35: PETROLEO | H35: YERBABUENA
A36: 46218156 | B36: GEINER ZAVALETA TAFUR | C36: W46218156 | D36: A2B | E36: AMBULANCIA | F36: NO TIENE | G36: PETROLEO | H36: ZARUMILLA
A37: 48515797 | B37: LLUNER ESTEBES MARIN DAMACEN | C37: W48515797 | D37: A2B | E37: TOYOTA HILUX 22R | F37: EUD-262 | G37: GASOLINA | H37: COCABAMBA
A38: 16712192 | B38: ALBERTO FARRO PEREZ | C38: C16712192 | D38: A2B | E38: TOYOYA HILUX | F38: EGO-124 | G38: PETROLEO | H38: OCALLI
A39: 44703306 | B39: RONAL SAUCEDO GUEVARA | C39: W44703306 | D39: A2B | E39: TIPO I | F39: EUB-067 | G39: GASOLINA | H39: BUENOS AIRES
A40: 75492112 | B40: NAIDER TELLO ESTELA | C40: Q75492112 | D40: A2B | E40: TOYOTA HILUX 4X4 | F40: EUH-708 | G40: PETROLEO | H40: COCOCHO
A43: NOTA: Agregue conductores faltantes al final. Las formulas los reconocen automaticamente.

Sheet DETALLE IPRESS
A1: DETALLE DE COMBUSTIBLE PENDIENTE DE ENTREGA POR IPRESS - 2026
A2: Se actualiza automáticamente — Al completar FECHA ENTREGA + OFICIO + O/C desaparece solo
A3: 🔍 SELECCIONAR IPRESS: | E3: OMIA
A5: ⛽ TOTAL GAL. PETRÓLEO: | C5: =IF($E$3="-- TODOS --",IFERROR(SUMPRODUCT((_PENDIENTES!$F$2:$F$1261="PETROLEO")*(_PENDIENTES!$G$2:$G$1261)),0),IFERROR(SUMPRODUCT((_PENDIENTES!$B$2:$B$1261=$E$3)*(_PENDIENTES!$F$2:$F$1261="PETROLEO")*(_PENDIENTES!$G$2:$G$1261)),0)) -> 0 | E5: ⛽ TOTAL GAL. GASOLINA: | G5: =IF($E$3="-- TODOS --",IFERROR(SUMPRODUCT((_PENDIENTES!$F$2:$F$1261="GASOLINA")*(_PENDIENTES!$G$2:$G$1261)),0),IFERROR(SUMPRODUCT((_PENDIENTES!$B$2:$B$1261=$E$3)*(_PENDIENTES!$F$2:$F$1261="GASOLINA")*(_PENDIENTES!$G$2:$G$1261)),0)) -> 0 | I5: 💰 TOTAL SOLES S/.: | K5: =IF($E$3="-- TODOS --",IFERROR(SUM(_PENDIENTES!$H$2:$H$1261),0),IFERROR(SUMPRODUCT((_PENDIENTES!$B$2:$B$1261=$E$3)*(_PENDIENTES!$H$2:$H$1261)),0)) -> 0
A7: N° | B7: MES | C7: AFILIADO | D7: NRO DOC | E7: FECHA | F7: TIPO | G7: GALONES | H7: TOTAL S/. | I7: CONDUCTOR | J7: PLACA | K7: ESTADO | L7: ENTREGAR / DEVOLVER | M7: IPRESS_KEY | N7: IPRESS ORIGEN
A8: =IF(_PENDIENTES!$B$2<>"",1,"") -> 1 | B8: =IF(_PENDIENTES!$B$2<>"",_PENDIENTES!$A$2,"") -> ENE | C8: =IF(_PENDIENTES!$B$2<>"",_PENDIENTES!$C$2,"") -> CIEZA RIOS AYLANI ELIZABETH | D8: =IF(_PENDIENTES!$B$2<>"",_PENDIENTES!$D$2,"") -> 94063517 | E8: =IF(_PENDIENTES!$B$2<>"",_PENDIENTES!$E$2,"") -> 01/01/2026 | F8: =IF(_PENDIENTES!$B$2<>"",_PENDIENTES!$F$2,"") -> PETROLEO | G8: =IF(_PENDIENTES!$B$2<>"",_PENDIENTES!$G$2,"") -> 6 | H8: =IF(_PENDIENTES!$B$2<>"",_PENDIENTES!$H$2,"") -> 109.08 | I8: =IF(_PENDIENTES!$B$2<>"",_PENDIENTES!$I$2,"") -> CARRERA ARAUJO JEINER | J8: =IF(_PENDIENTES!$B$2<>"",_PENDIENTES!$J$2,"") -> EUH747 | K8: =IF(_PENDIENTES!$B$2<>"","POR RECOGER","") -> POR RECOGER | L8: =IF(_PENDIENTES!$B$2<>"",_PENDIENTES!$K$2,"") -> 0 | M8: =IF(_PENDIENTES!$B$2<>"",_PENDIENTES!$B$2,"") -> POMACOCHAS | N8: =IF(_PENDIENTES!$B$2<>"",_PENDIENTES!$L$2,"") -> POMACOCHAS
A9: =IF(_PENDIENTES!$B$3<>"",2,"") -> 2 | B9: =IF(_PENDIENTES!$B$3<>"",_PENDIENTES!$A$3,"") -> ENE | C9: =IF(_PENDIENTES!$B$3<>"",_PENDIENTES!$C$3,"") -> DIAZ MESIA DIANELIT THALIA | D9: =IF(_PENDIENTES!$B$3<>"",_PENDIENTES!$D$3,"") -> 75729771 | E9: =IF(_PENDIENTES!$B$3<>"",_PENDIENTES!$E$3,"") -> 02/01/2026 | F9: =IF(_PENDIENTES!$B$3<>"",_PENDIENTES!$F$3,"") -> PETROLEO | G9: =IF(_PENDIENTES!$B$3<>"",_PENDIENTES!$G$3,"") -> 7 | H9: =IF(_PENDIENTES!$B$3<>"",_PENDIENTES!$H$3,"") -> 127.26 | I9: =IF(_PENDIENTES!$B$3<>"",_PENDIENTES!$I$3,"") -> BUELOT VISALOT CARLO MAGNO | J9: =IF(_PENDIENTES!$B$3<>"",_PENDIENTES!$J$3,"") -> EUD 634 | K9: =IF(_PENDIENTES!$B$3<>"","POR RECOGER","") -> POR RECOGER | L9: =IF(_PENDIENTES!$B$3<>"",_PENDIENTES!$K$3,"") -> 0 | M9: =IF(_PENDIENTES!$B$3<>"",_PENDIENTES!$B$3,"") -> COLCAMAR | N9: =IF(_PENDIENTES!$B$3<>"",_PENDIENTES!$L$3,"") -> COLCAMAR
A10: =IF(_PENDIENTES!$B$4<>"",3,"") -> 3 | B10: =IF(_PENDIENTES!$B$4<>"",_PENDIENTES!$A$4,"") -> ENE | C10: =IF(_PENDIENTES!$B$4<>"",_PENDIENTES!$C$4,"") -> ZELADA SANTILLAN EWHAN ADIEL | D10: =IF(_PENDIENTES!$B$4<>"",_PENDIENTES!$D$4,"") -> 92682700 | E10: =IF(_PENDIENTES!$B$4<>"",_PENDIENTES!$E$4,"") -> 02/01/2026 | F10: =IF(_PENDIENTES!$B$4<>"",_PENDIENTES!$F$4,"") -> PETROLEO | G10: =IF(_PENDIENTES!$B$4<>"",_PENDIENTES!$G$4,"") -> 7 | H10: =IF(_PENDIENTES!$B$4<>"",_PENDIENTES!$H$4,"") -> 141.75 | I10: =IF(_PENDIENTES!$B$4<>"",_PENDIENTES!$I$4,"") -> SERNAQUE PELAEZ WILMER | J10: =IF(_PENDIENTES!$B$4<>"",_PENDIENTES!$J$4,"") -> EUH-421 | K10: =IF(_PENDIENTES!$B$4<>"","POR RECOGER","") -> POR RECOGER | L10: =IF(_PENDIENTES!$B$4<>"",_PENDIENTES!$K$4,"") -> 0 | M10: =IF(_PENDIENTES!$B$4<>"",_PENDIENTES!$B$4,"") -> MARIA AUXILIADORA | N10: =IF(_PENDIENTES!$B$4<>"",_PENDIENTES!$L$4,"") -> MARIA AUXILIADORA
A11: =IF(_PENDIENTES!$B$5<>"",4,"") -> 4 | B11: =IF(_PENDIENTES!$B$5<>"",_PENDIENTES!$A$5,"") -> ENE | C11: =IF(_PENDIENTES!$B$5<>"",_PENDIENTES!$C$5,"") -> RODRIGUEZ CALDERON JESUS SALVADOR | D11: =IF(_PENDIENTES!$B$5<>"",_PENDIENTES!$D$5,"") -> 33950773 | E11: =IF(_PENDIENTES!$B$5<>"",_PENDIENTES!$E$5,"") -> 03/01/2026 | F11: =IF(_PENDIENTES!$B$5<>"",_PENDIENTES!$F$5,"") -> PETROLEO | G11: =IF(_PENDIENTES!$B$5<>"",_PENDIENTES!$G$5,"") -> 7 | H11: =IF(_PENDIENTES!$B$5<>"",_PENDIENTES!$H$5,"") -> 141.75 | I11: =IF(_PENDIENTES!$B$5<>"",_PENDIENTES!$I$5,"") | J11: =IF(_PENDIENTES!$B$5<>"",_PENDIENTES!$J$5,"") | K11: =IF(_PENDIENTES!$B$5<>"","POR RECOGER","") -> POR RECOGER | L11: =IF(_PENDIENTES!$B$5<>"",_PENDIENTES!$K$5,"") -> 0 | M11: =IF(_PENDIENTES!$B$5<>"",_PENDIENTES!$B$5,"") -> MARIA AUXILIADORA | N11: =IF(_PENDIENTES!$B$5<>"",_PENDIENTES!$L$5,"") -> MARIA AUXILIADORA
A12: =IF(_PENDIENTES!$B$6<>"",5,"") -> 5 | B12: =IF(_PENDIENTES!$B$6<>"",_PENDIENTES!$A$6,"") -> ENE | C12: =IF(_PENDIENTES!$B$6<>"",_PENDIENTES!$C$6,"") -> HUAMAN HUAMAN LUZ CLARITA | D12: =IF(_PENDIENTES!$B$6<>"",_PENDIENTES!$D$6,"") -> 73632523 | E12: =IF(_PENDIENTES!$B$6<>"",_PENDIENTES!$E$6,"") -> 04/01/2026 | F12: =IF(_PENDIENTES!$B$6<>"",_PENDIENTES!$F$6,"") -> PETROLEO | G12: =IF(_PENDIENTES!$B$6<>"",_PENDIENTES!$G$6,"") -> 7 | H12: =IF(_PENDIENTES!$B$6<>"",_PENDIENTES!$H$6,"") -> 141.75 | I12: =IF(_PENDIENTES!$B$6<>"",_PENDIENTES!$I$6,"") -> ROJAS ALVARADO BENJAMIN | J12: =IF(_PENDIENTES!$B$6<>"",_PENDIENTES!$J$6,"") -> 421 EUH | K12: =IF(_PENDIENTES!$B$6<>"","POR RECOGER","") -> POR RECOGER | L12: =IF(_PENDIENTES!$B$6<>"",_PENDIENTES!$K$6,"") -> 0 | M12: =IF(_PENDIENTES!$B$6<>"",_PENDIENTES!$B$6,"") -> MARIA AUXILIADORA | N12: =IF(_PENDIENTES!$B$6<>"",_PENDIENTES!$L$6,"") -> MARIA AUXILIADORA
A13: =IF(_PENDIENTES!$B$7<>"",6,"") -> 6 | B13: =IF(_PENDIENTES!$B$7<>"",_PENDIENTES!$A$7,"") -> ENE | C13: =IF(_PENDIENTES!$B$7<>"",_PENDIENTES!$C$7,"") -> GUSMAN ALVARADO CESAR | D13: =IF(_PENDIENTES!$B$7<>"",_PENDIENTES!$D$7,"") -> 45825389 | E13: =IF(_PENDIENTES!$B$7<>"",_PENDIENTES!$E$7,"") -> 05/01/2026 | F13: =IF(_PENDIENTES!$B$7<>"",_PENDIENTES!$F$7,"") -> PETROLEO | G13: =IF(_PENDIENTES!$B$7<>"",_PENDIENTES!$G$7,"") -> 7 | H13: =IF(_PENDIENTES!$B$7<>"",_PENDIENTES!$H$7,"") -> 127.26 | I13: =IF(_PENDIENTES!$B$7<>"",_PENDIENTES!$I$7,"") -> BUELOT VISALOT CARLO MAGNO | J13: =IF(_PENDIENTES!$B$7<>"",_PENDIENTES!$J$7,"") -> EUD 634 | K13: =IF(_PENDIENTES!$B$7<>"","POR RECOGER","") -> POR RECOGER | L13: =IF(_PENDIENTES!$B$7<>"",_PENDIENTES!$K$7,"") -> 0 | M13: =IF(_PENDIENTES!$B$7<>"",_PENDIENTES!$B$7,"") -> COLCAMAR | N13: =IF(_PENDIENTES!$B$7<>"",_PENDIENTES!$L$7,"") -> COLCAMAR
A14: =IF(_PENDIENTES!$B$8<>"",7,"") -> 7 | B14: =IF(_PENDIENTES!$B$8<>"",_PENDIENTES!$A$8,"") -> ENE | C14: =IF(_PENDIENTES!$B$8<>"",_PENDIENTES!$C$8,"") -> PORTOCARRERO GRANDEZ GLORIA VILMITA | D14: =IF(_PENDIENTES!$B$8<>"",_PENDIENTES!$D$8,"") -> 43504295 | E14: =IF(_PENDIENTES!$B$8<>"",_PENDIENTES!$E$8,"") -> 05/01/2026 | F14: =IF(_PENDIENTES!$B$8<>"",_PENDIENTES!$F$8,"") -> PETROLEO | G14: =IF(_PENDIENTES!$B$8<>"",_PENDIENTES!$G$8,"") -> 7 | H14: =IF(_PENDIENTES!$B$8<>"",_PENDIENTES!$H$8,"") -> 141.75 | I14: =IF(_PENDIENTES!$B$8<>"",_PENDIENTES!$I$8,"") | J14: =IF(_PENDIENTES!$B$8<>"",_PENDIENTES!$J$8,"") | K14: =IF(_PENDIENTES!$B$8<>"","POR RECOGER","") -> POR RECOGER | L14: =IF(_PENDIENTES!$B$8<>"",_PENDIENTES!$K$8,"") -> 0 | M14: =IF(_PENDIENTES!$B$8<>"",_PENDIENTES!$B$8,"") -> MARIA AUXILIADORA | N14: =IF(_PENDIENTES!$B$8<>"",_PENDIENTES!$L$8,"") -> MARIA AUXILIADORA
A15: =IF(_PENDIENTES!$B$9<>"",8,"") -> 8 | B15: =IF(_PENDIENTES!$B$9<>"",_PENDIENTES!$A$9,"") -> ENE | C15: =IF(_PENDIENTES!$B$9<>"",_PENDIENTES!$C$9,"") -> VARGAS TUESTA BRISTYN PAOLO | D15: =IF(_PENDIENTES!$B$9<>"",_PENDIENTES!$D$9,"") -> 91225101 | E15: =IF(_PENDIENTES!$B$9<>"",_PENDIENTES!$E$9,"") -> 06/01/2026 | F15: =IF(_PENDIENTES!$B$9<>"",_PENDIENTES!$F$9,"") -> PETROLEO | G15: =IF(_PENDIENTES!$B$9<>"",_PENDIENTES!$G$9,"") -> 10 | H15: =IF(_PENDIENTES!$B$9<>"",_PENDIENTES!$H$9,"") -> 202.5 | I15: =IF(_PENDIENTES!$B$9<>"",_PENDIENTES!$I$9,"") -> LOPEZ HOYOS MIGUEL ANGEL | J15: =IF(_PENDIENTES!$B$9<>"",_PENDIENTES!$J$9,"") -> EUH-698 | K15: =IF(_PENDIENTES!$B$9<>"","POR RECOGER","") -> POR RECOGER | L15: =IF(_PENDIENTES!$B$9<>"",_PENDIENTES!$K$9,"") -> HUAMBO | M15: =IF(_PENDIENTES!$B$9<>"",_PENDIENTES!$B$9,"") -> HUAMBO | N15: =IF(_PENDIENTES!$B$9<>"",_PENDIENTES!$L$9,"") -> MARIA AUXILIADORA
A16: =IF(_PENDIENTES!$B$10<>"",9,"") -> 9 | B16: =IF(_PENDIENTES!$B$10<>"",_PENDIENTES!$A$10,"") -> ENE | C16: =IF(_PENDIENTES!$B$10<>"",_PENDIENTES!$C$10,"") -> LEON DELGADO EIMI YAMILET | D16: =IF(_PENDIENTES!$B$10<>"",_PENDIENTES!$D$10,"") -> 61561896 | E16: =IF(_PENDIENTES!$B$10<>"",_PENDIENTES!$E$10,"") -> 06/01/2025 | F16: =IF(_PENDIENTES!$B$10<>"",_PENDIENTES!$F$10,"") -> PETROLEO | G16: =IF(_PENDIENTES!$B$10<>"",_PENDIENTES!$G$10,"") -> 5 | H16: =IF(_PENDIENTES!$B$10<>"",_PENDIENTES!$H$10,"") -> 90.9 | I16: =IF(_PENDIENTES!$B$10<>"",_PENDIENTES!$I$10,"") -> BRICENO OXOLON MANUEL | J16: =IF(_PENDIENTES!$B$10<>"",_PENDIENTES!$J$10,"") -> EUC976 | K16: =IF(_PENDIENTES!$B$10<>"","POR RECOGER","") -> POR RECOGER | L16: =IF(_PENDIENTES!$B$10<>"",_PENDIENTES!$K$10,"") -> 0 | M16: =IF(_PENDIENTES!$B$10<>"",_PENDIENTES!$B$10,"") -> JUMBILLA | N16: =IF(_PENDIENTES!$B$10<>"",_PENDIENTES!$L$10,"") -> JUMBILLA
A17: =IF(_PENDIENTES!$B$11<>"",10,"") -> 10 | B17: =IF(_PENDIENTES!$B$11<>"",_PENDIENTES!$A$11,"") -> ENE | C17: =IF(_PENDIENTES!$B$11<>"",_PENDIENTES!$C$11,"") -> TAFUR LOPEZ SEGUNDO PACIFICO | D17: =IF(_PENDIENTES!$B$11<>"",_PENDIENTES!$D$11,"") -> 44932120 | E17: =IF(_PENDIENTES!$B$11<>"",_PENDIENTES!$E$11,"") -> 07/01/2026 | F17: =IF(_PENDIENTES!$B$11<>"",_PENDIENTES!$F$11,"") -> PETROLEO | G17: =IF(_PENDIENTES!$B$11<>"",_PENDIENTES!$G$11,"") -> 7 | H17: =IF(_PENDIENTES!$B$11<>"",_PENDIENTES!$H$11,"") -> 141.75 | I17: =IF(_PENDIENTES!$B$11<>"",_PENDIENTES!$I$11,"") | J17: =IF(_PENDIENTES!$B$11<>"",_PENDIENTES!$J$11,"") | K17: =IF(_PENDIENTES!$B$11<>"","POR RECOGER","") -> POR RECOGER | L17: =IF(_PENDIENTES!$B$11<>"",_PENDIENTES!$K$11,"") -> 0 | M17: =IF(_PENDIENTES!$B$11<>"",_PENDIENTES!$B$11,"") -> MARIA AUXILIADORA | N17: =IF(_PENDIENTES!$B$11<>"",_PENDIENTES!$L$11,"") -> MARIA AUXILIADORA
A18: =IF(_PENDIENTES!$B$12<>"",11,"") -> 11 | B18: =IF(_PENDIENTES!$B$12<>"",_PENDIENTES!$A$12,"") -> ENE | C18: =IF(_PENDIENTES!$B$12<>"",_PENDIENTES!$C$12,"") -> VILLA LOPEZ NEILI DANITZA | D18: =IF(_PENDIENTES!$B$12<>"",_PENDIENTES!$D$12,"") -> 44401644 | E18: =IF(_PENDIENTES!$B$12<>"",_PENDIENTES!$E$12,"") -> 08/01/2026 | F18: =IF(_PENDIENTES!$B$12<>"",_PENDIENTES!$F$12,"") -> PETROLEO | G18: =IF(_PENDIENTES!$B$12<>"",_PENDIENTES!$G$12,"") -> 7 | H18: =IF(_PENDIENTES!$B$12<>"",_PENDIENTES!$H$12,"") -> 141.75 | I18: =IF(_PENDIENTES!$B$12<>"",_PENDIENTES!$I$12,"") -> ROJAS ALVARADO BENJAMIN | J18: =IF(_PENDIENTES!$B$12<>"",_PENDIENTES!$J$12,"") -> 421 EUH | K18: =IF(_PENDIENTES!$B$12<>"","POR RECOGER","") -> POR RECOGER | L18: =IF(_PENDIENTES!$B$12<>"",_PENDIENTES!$K$12,"") -> 0 | M18: =IF(_PENDIENTES!$B$12<>"",_PENDIENTES!$B$12,"") -> MARIA AUXILIADORA | N18: =IF(_PENDIENTES!$B$12<>"",_PENDIENTES!$L$12,"") -> MARIA AUXILIADORA
A19: =IF(_PENDIENTES!$B$13<>"",12,"") -> 12 | B19: =IF(_PENDIENTES!$B$13<>"",_PENDIENTES!$A$13,"") -> ENE | C19: =IF(_PENDIENTES!$B$13<>"",_PENDIENTES!$C$13,"") -> FERNANDEZ LOPEZ GIL AUGUSTO | D19: =IF(_PENDIENTES!$B$13<>"",_PENDIENTES!$D$13,"") -> 33946545 | E19: =IF(_PENDIENTES!$B$13<>"",_PENDIENTES!$E$13,"") -> 09/01/2026 | F19: =IF(_PENDIENTES!$B$13<>"",_PENDIENTES!$F$13,"") -> PETROLEO | G19: =IF(_PENDIENTES!$B$13<>"",_PENDIENTES!$G$13,"") -> 7 | H19: =IF(_PENDIENTES!$B$13<>"",_PENDIENTES!$H$13,"") -> 141.75 | I19: =IF(_PENDIENTES!$B$13<>"",_PENDIENTES!$I$13,"") -> TRIGOSO TAFUR JOSE GILBER | J19: =IF(_PENDIENTES!$B$13<>"",_PENDIENTES!$J$13,"") -> EUH 421 | K19: =IF(_PENDIENTES!$B$13<>"","POR RECOGER","") -> POR RECOGER | L19: =IF(_PENDIENTES!$B$13<>"",_PENDIENTES!$K$13,"") -> 0 | M19: =IF(_PENDIENTES!$B$13<>"",_PENDIENTES!$B$13,"") -> MARIA AUXILIADORA | N19: =IF(_PENDIENTES!$B$13<>"",_PENDIENTES!$L$13,"") -> MARIA AUXILIADORA
A20: =IF(_PENDIENTES!$B$14<>"",13,"") -> 13 | B20: =IF(_PENDIENTES!$B$14<>"",_PENDIENTES!$A$14,"") -> ENE | C20: =IF(_PENDIENTES!$B$14<>"",_PENDIENTES!$C$14,"") -> ARANA LOPEZ MARILIZ MISHEL | D20: =IF(_PENDIENTES!$B$14<>"",_PENDIENTES!$D$14,"") -> 78095143 | E20: =IF(_PENDIENTES!$B$14<>"",_PENDIENTES!$E$14,"") -> 10/01/2026 | F20: =IF(_PENDIENTES!$B$14<>"",_PENDIENTES!$F$14,"") -> PETROLEO | G20: =IF(_PENDIENTES!$B$14<>"",_PENDIENTES!$G$14,"") -> 6.8 | H20: =IF(_PENDIENTES!$B$14<>"",_PENDIENTES!$H$14,"") -> 137.7 | I20: =IF(_PENDIENTES!$B$14<>"",_PENDIENTES!$I$14,"") -> TRIGOSO TAFUR JOSE GILBER | J20: =IF(_PENDIENTES!$B$14<>"",_PENDIENTES!$J$14,"") -> EUH 421 | K20: =IF(_PENDIENTES!$B$14<>"","POR RECOGER","") -> POR RECOGER | L20: =IF(_PENDIENTES!$B$14<>"",_PENDIENTES!$K$14,"") -> 0 | M20: =IF(_PENDIENTES!$B$14<>"",_PENDIENTES!$B$14,"") -> MARIA AUXILIADORA | N20: =IF(_PENDIENTES!$B$14<>"",_PENDIENTES!$L$14,"") -> MARIA AUXILIADORA
A21: =IF(_PENDIENTES!$B$15<>"",14,"") -> 14 | B21: =IF(_PENDIENTES!$B$15<>"",_PENDIENTES!$A$15,"") -> ENE | C21: =IF(_PENDIENTES!$B$15<>"",_PENDIENTES!$C$15,"") -> LUCERO TUESTA MARBELI | D21: =IF(_PENDIENTES!$B$15<>"",_PENDIENTES!$D$15,"") -> 63365856 | E21: =IF(_PENDIENTES!$B$15<>"",_PENDIENTES!$E$15,"") -> 12/01/2026 | F21: =IF(_PENDIENTES!$B$15<>"",_PENDIENTES!$F$15,"") -> PETROLEO | G21: =IF(_PENDIENTES!$B$15<>"",_PENDIENTES!$G$15,"") -> 5 | H21: =IF(_PENDIENTES!$B$15<>"",_PENDIENTES!$H$15,"") -> 101.25 | I21: =IF(_PENDIENTES!$B$15<>"",_PENDIENTES!$I$15,"") -> ROJAS ALVARADO BENJAMIN | J21: =IF(_PENDIENTES!$B$15<>"",_PENDIENTES!$J$15,"") -> 421 EUH | K21: =IF(_PENDIENTES!$B$15<>"","POR RECOGER","") -> POR RECOGER | L21: =IF(_PENDIENTES!$B$15<>"",_PENDIENTES!$K$15,"") -> 0 | M21: =IF(_PENDIENTES!$B$15<>"",_PENDIENTES!$B$15,"") -> MARIA AUXILIADORA | N21: =IF(_PENDIENTES!$B$15<>"",_PENDIENTES!$L$15,"") -> MARIA AUXILIADORA
A22: =IF(_PENDIENTES!$B$16<>"",15,"") -> 15 | B22: =IF(_PENDIENTES!$B$16<>"",_PENDIENTES!$A$16,"") -> ENE | C22: =IF(_PENDIENTES!$B$16<>"",_PENDIENTES!$C$16,"") -> REYES VASQUEZ JOAO YADIEL | D22: =IF(_PENDIENTES!$B$16<>"",_PENDIENTES!$D$16,"") -> 94359638 | E22: =IF(_PENDIENTES!$B$16<>"",_PENDIENTES!$E$16,"") -> 14/01/2026 | F22: =IF(_PENDIENTES!$B$16<>"",_PENDIENTES!$F$16,"") -> PETROLEO | G22: =IF(_PENDIENTES!$B$16<>"",_PENDIENTES!$G$16,"") -> 6 | H22: =IF(_PENDIENTES!$B$16<>"",_PENDIENTES!$H$16,"") -> 109.08 | I22: =IF(_PENDIENTES!$B$16<>"",_PENDIENTES!$I$16,"") -> CARRERA ARAUJO JEINER | J22: =IF(_PENDIENTES!$B$16<>"",_PENDIENTES!$J$16,"") -> EUH747 | K22: =IF(_PENDIENTES!$B$16<>"","POR RECOGER","") -> POR RECOGER | L22: =IF(_PENDIENTES!$B$16<>"",_PENDIENTES!$K$16,"") -> 0 | M22: =IF(_PENDIENTES!$B$16<>"",_PENDIENTES!$B$16,"") -> POMACOCHAS | N22: =IF(_PENDIENTES!$B$16<>"",_PENDIENTES!$L$16,"") -> POMACOCHAS
A23: =IF(_PENDIENTES!$B$17<>"",16,"") -> 16 | B23: =IF(_PENDIENTES!$B$17<>"",_PENDIENTES!$A$17,"") -> ENE | C23: =IF(_PENDIENTES!$B$17<>"",_PENDIENTES!$C$17,"") -> CASTRO DE VARGAS JUSTINA | D23: =IF(_PENDIENTES!$B$17<>"",_PENDIENTES!$D$17,"") -> 33944106 | E23: =IF(_PENDIENTES!$B$17<>"",_PENDIENTES!$E$17,"") -> 14/01/2026 | F23: =IF(_PENDIENTES!$B$17<>"",_PENDIENTES!$F$17,"") -> PETROLEO | G23: =IF(_PENDIENTES!$B$17<>"",_PENDIENTES!$G$17,"") -> 7 | H23: =IF(_PENDIENTES!$B$17<>"",_PENDIENTES!$H$17,"") -> 141.75 | I23: =IF(_PENDIENTES!$B$17<>"",_PENDIENTES!$I$17,"") -> TRIGOSO TAFUR JOSE GILBER | J23: =IF(_PENDIENTES!$B$17<>"",_PENDIENTES!$J$17,"") -> EUH 421 | K23: =IF(_PENDIENTES!$B$17<>"","POR RECOGER","") -> POR RECOGER | L23: =IF(_PENDIENTES!$B$17<>"",_PENDIENTES!$K$17,"") -> 0 | M23: =IF(_PENDIENTES!$B$17<>"",_PENDIENTES!$B$17,"") -> MARIA AUXILIADORA | N23: =IF(_PENDIENTES!$B$17<>"",_PENDIENTES!$L$17,"") -> MARIA AUXILIADORA
A24: =IF(_PENDIENTES!$B$18<>"",17,"") -> 17 | B24: =IF(_PENDIENTES!$B$18<>"",_PENDIENTES!$A$18,"") -> ENE | C24: =IF(_PENDIENTES!$B$18<>"",_PENDIENTES!$C$18,"") -> OBLITAS VASQUEZ YENNY | D24: =IF(_PENDIENTES!$B$18<>"",_PENDIENTES!$D$18,"") -> 77346512 | E24: =IF(_PENDIENTES!$B$18<>"",_PENDIENTES!$E$18,"") -> 17/01/2026 | F24: =IF(_PENDIENTES!$B$18<>"",_PENDIENTES!$F$18,"") -> PETROLEO | G24: =IF(_PENDIENTES!$B$18<>"",_PENDIENTES!$G$18,"") -> 6 | H24: =IF(_PENDIENTES!$B$18<>"",_PENDIENTES!$H$18,"") -> 109.08 | I24: =IF(_PENDIENTES!$B$18<>"",_PENDIENTES!$I$18,"") -> CARRERA ARAUJO JEINER | J24: =IF(_PENDIENTES!$B$18<>"",_PENDIENTES!$J$18,"") -> EUH747 | K24: =IF(_PENDIENTES!$B$18<>"","POR RECOGER","") -> POR RECOGER | L24: =IF(_PENDIENTES!$B$18<>"",_PENDIENTES!$K$18,"") -> 0 | M24: =IF(_PENDIENTES!$B$18<>"",_PENDIENTES!$B$18,"") -> POMACOCHAS | N24: =IF(_PENDIENTES!$B$18<>"",_PENDIENTES!$L$18,"") -> POMACOCHAS
A25: =IF(_PENDIENTES!$B$19<>"",18,"") -> 18 | B25: =IF(_PENDIENTES!$B$19<>"",_PENDIENTES!$A$19,"") -> ENE | C25: =IF(_PENDIENTES!$B$19<>"",_PENDIENTES!$C$19,"") -> TAFUR SALDAÑA JUAN ALBERTO | D25: =IF(_PENDIENTES!$B$19<>"",_PENDIENTES!$D$19,"") -> 33941504 | E25: =IF(_PENDIENTES!$B$19<>"",_PENDIENTES!$E$19,"") -> 17/01/2026 | F25: =IF(_PENDIENTES!$B$19<>"",_PENDIENTES!$F$19,"") -> PETROLEO | G25: =IF(_PENDIENTES!$B$19<>"",_PENDIENTES!$G$19,"") -> 7 | H25: =IF(_PENDIENTES!$B$19<>"",_PENDIENTES!$H$19,"") -> 141.75 | I25: =IF(_PENDIENTES!$B$19<>"",_PENDIENTES!$I$19,"") -> TRIGOSO TAFUR JOSE GILBER | J25: =IF(_PENDIENTES!$B$19<>"",_PENDIENTES!$J$19,"") -> EUH 421 | K25: =IF(_PENDIENTES!$B$19<>"","POR RECOGER","") -> POR RECOGER | L25: =IF(_PENDIENTES!$B$19<>"",_PENDIENTES!$K$19,"") -> 0 | M25: =IF(_PENDIENTES!$B$19<>"",_PENDIENTES!$B$19,"") -> MARIA AUXILIADORA | N25: =IF(_PENDIENTES!$B$19<>"",_PENDIENTES!$L$19,"") -> MARIA AUXILIADORA
A26: =IF(_PENDIENTES!$B$20<>"",19,"") -> 19 | B26: =IF(_PENDIENTES!$B$20<>"",_PENDIENTES!$A$20,"") -> ENE | C26: =IF(_PENDIENTES!$B$20<>"",_PENDIENTES!$C$20,"") -> LOPEZ VILCAROMERO MARIKELI | D26: =IF(_PENDIENTES!$B$20<>"",_PENDIENTES!$D$20,"") -> 60526420 | E26: =IF(_PENDIENTES!$B$20<>"",_PENDIENTES!$E$20,"") -> 18/01/2026 | F26: =IF(_PENDIENTES!$B$20<>"",_PENDIENTES!$F$20,"") -> PETROLEO | G26: =IF(_PENDIENTES!$B$20<>"",_PENDIENTES!$G$20,"") -> 6 | H26: =IF(_PENDIENTES!$B$20<>"",_PENDIENTES!$H$20,"") -> 121.5 | I26: =IF(_PENDIENTES!$B$20<>"",_PENDIENTES!$I$20,"") -> SERNAQUE PELAEZ WILMER | J26: =IF(_PENDIENTES!$B$20<>"",_PENDIENTES!$J$20,"") -> EUH-421 | K26: =IF(_PENDIENTES!$B$20<>"","POR RECOGER","") -> POR RECOGER | L26: =IF(_PENDIENTES!$B$20<>"",_PENDIENTES!$K$20,"") -> 0 | M26: =IF(_PENDIENTES!$B$20<>"",_PENDIENTES!$B$20,"") -> MARIA AUXILIADORA | N26: =IF(_PENDIENTES!$B$20<>"",_PENDIENTES!$L$20,"") -> MARIA AUXILIADORA
A27: =IF(_PENDIENTES!$B$21<>"",20,"") -> 20 | B27: =IF(_PENDIENTES!$B$21<>"",_PENDIENTES!$A$21,"") -> ENE | C27: =IF(_PENDIENTES!$B$21<>"",_PENDIENTES!$C$21,"") -> CHAVEZ AREVALO FLORES MILA | D27: =IF(_PENDIENTES!$B$21<>"",_PENDIENTES!$D$21,"") -> 72686690 | E27: =IF(_PENDIENTES!$B$21<>"",_PENDIENTES!$E$21,"") -> 19/01/2026 | F27: =IF(_PENDIENTES!$B$21<>"",_PENDIENTES!$F$21,"") -> PETROLEO | G27: =IF(_PENDIENTES!$B$21<>"",_PENDIENTES!$G$21,"") -> 5 | H27: =IF(_PENDIENTES!$B$21<>"",_PENDIENTES!$H$21,"") -> 90.9 | I27: =IF(_PENDIENTES!$B$21<>"",_PENDIENTES!$I$21,"") -> VILCARROMERO TORREJON HERMERSON | J27: =IF(_PENDIENTES!$B$21<>"",_PENDIENTES!$J$21,"") -> EUD-917 | K27: =IF(_PENDIENTES!$B$21<>"","POR RECOGER","") -> POR RECOGER | L27: =IF(_PENDIENTES!$B$21<>"",_PENDIENTES!$K$21,"") -> 0 | M27: =IF(_PENDIENTES!$B$21<>"",_PENDIENTES!$B$21,"") -> TINGO | N27: =IF(_PENDIENTES!$B$21<>"",_PENDIENTES!$L$21,"") -> TINGO
A28: =IF(_PENDIENTES!$B$22<>"",21,"") -> 21 | B28: =IF(_PENDIENTES!$B$22<>"",_PENDIENTES!$A$22,"") -> ENE | C28: =IF(_PENDIENTES!$B$22<>"",_PENDIENTES!$C$22,"") -> SANCHEZ REVILLA JHOSELI MANUELITA | D28: =IF(_PENDIENTES!$B$22<>"",_PENDIENTES!$D$22,"") -> 60035393 | E28: =IF(_PENDIENTES!$B$22<>"",_PENDIENTES!$E$22,"") -> 19/01/2026 | F28: =IF(_PENDIENTES!$B$22<>"",_PENDIENTES!$F$22,"") -> PETROLEO | G28: =IF(_PENDIENTES!$B$22<>"",_PENDIENTES!$G$22,"") -> 7 | H28: =IF(_PENDIENTES!$B$22<>"",_PENDIENTES!$H$22,"") -> 141.75 | I28: =IF(_PENDIENTES!$B$22<>"",_PENDIENTES!$I$22,"") -> TRIGOSO TAFUR JOSE GILBER | J28: =IF(_PENDIENTES!$B$22<>"",_PENDIENTES!$J$22,"") -> EUH 421 | K28: =IF(_PENDIENTES!$B$22<>"","POR RECOGER","") -> POR RECOGER | L28: =IF(_PENDIENTES!$B$22<>"",_PENDIENTES!$K$22,"") -> 0 | M28: =IF(_PENDIENTES!$B$22<>"",_PENDIENTES!$B$22,"") -> MARIA AUXILIADORA | N28: =IF(_PENDIENTES!$B$22<>"",_PENDIENTES!$L$22,"") -> MARIA AUXILIADORA
A29: =IF(_PENDIENTES!$B$23<>"",22,"") -> 22 | B29: =IF(_PENDIENTES!$B$23<>"",_PENDIENTES!$A$23,"") -> ENE | C29: =IF(_PENDIENTES!$B$23<>"",_PENDIENTES!$C$23,"") -> SILVA TAFUR DEICY MADAY | D29: =IF(_PENDIENTES!$B$23<>"",_PENDIENTES!$D$23,"") -> 40662457 | E29: =IF(_PENDIENTES!$B$23<>"",_PENDIENTES!$E$23,"") -> 20/01/2026 | F29: =IF(_PENDIENTES!$B$23<>"",_PENDIENTES!$F$23,"") -> PETROLEO | G29: =IF(_PENDIENTES!$B$23<>"",_PENDIENTES!$G$23,"") -> 5 | H29: =IF(_PENDIENTES!$B$23<>"",_PENDIENTES!$H$23,"") -> 90.9 | I29: =IF(_PENDIENTES!$B$23<>"",_PENDIENTES!$I$23,"") -> VILCARROMERO TORREJON HERMERSON | J29: =IF(_PENDIENTES!$B$23<>"",_PENDIENTES!$J$23,"") -> EUD-917 | K29: =IF(_PENDIENTES!$B$23<>"","POR RECOGER","") -> POR RECOGER | L29: =IF(_PENDIENTES!$B$23<>"",_PENDIENTES!$K$23,"") -> 0 | M29: =IF(_PENDIENTES!$B$23<>"",_PENDIENTES!$B$23,"") -> TINGO | N29: =IF(_PENDIENTES!$B$23<>"",_PENDIENTES!$L$23,"") -> TINGO
A30: =IF(_PENDIENTES!$B$24<>"",23,"") -> 23 | B30: =IF(_PENDIENTES!$B$24<>"",_PENDIENTES!$A$24,"") -> ENE | C30: =IF(_PENDIENTES!$B$24<>"",_PENDIENTES!$C$24,"") -> CRUZ CRUZ HILDA MERCEDES | D30: =IF(_PENDIENTES!$B$24<>"",_PENDIENTES!$D$24,"") -> 33420344 | E30: =IF(_PENDIENTES!$B$24<>"",_PENDIENTES!$E$24,"") -> 20/01/2026 | F30: =IF(_PENDIENTES!$B$24<>"",_PENDIENTES!$F$24,"") -> PETROLEO | G30: =IF(_PENDIENTES!$B$24<>"",_PENDIENTES!$G$24,"") -> 5 | H30: =IF(_PENDIENTES!$B$24<>"",_PENDIENTES!$H$24,"") -> 90.9 | I30: =IF(_PENDIENTES!$B$24<>"",_PENDIENTES!$I$24,"") -> VILCARROMERO TORREJON HERMERSON | J30: =IF(_PENDIENTES!$B$24<>"",_PENDIENTES!$J$24,"") -> EUD-917 | K30: =IF(_PENDIENTES!$B$24<>"","POR RECOGER","") -> POR RECOGER | L30: =IF(_PENDIENTES!$B$24<>"",_PENDIENTES!$K$24,"") -> 0 | M30: =IF(_PENDIENTES!$B$24<>"",_PENDIENTES!$B$24,"") -> TINGO | N30: =IF(_PENDIENTES!$B$24<>"",_PENDIENTES!$L$24,"") -> TINGO
A31: =IF(_PENDIENTES!$B$25<>"",24,"") -> 24 | B31: =IF(_PENDIENTES!$B$25<>"",_PENDIENTES!$A$25,"") -> ENE | C31: =IF(_PENDIENTES!$B$25<>"",_PENDIENTES!$C$25,"") -> MUÑOZ BUSTAMANTE MARINA MELANIA | D31: =IF(_PENDIENTES!$B$25<>"",_PENDIENTES!$D$25,"") -> 47349553 | E31: =IF(_PENDIENTES!$B$25<>"",_PENDIENTES!$E$25,"") -> 21/01/2026 | F31: =IF(_PENDIENTES!$B$25<>"",_PENDIENTES!$F$25,"") -> PETROLEO | G31: =IF(_PENDIENTES!$B$25<>"",_PENDIENTES!$G$25,"") -> 7 | H31: =IF(_PENDIENTES!$B$25<>"",_PENDIENTES!$H$25,"") -> 141.75 | I31: =IF(_PENDIENTES!$B$25<>"",_PENDIENTES!$I$25,"") -> TRIGOSO TAFUR JOSE GILBER | J31: =IF(_PENDIENTES!$B$25<>"",_PENDIENTES!$J$25,"") -> EUH 421 | K31: =IF(_PENDIENTES!$B$25<>"","POR RECOGER","") -> POR RECOGER | L31: =IF(_PENDIENTES!$B$25<>"",_PENDIENTES!$K$25,"") -> 0 | M31: =IF(_PENDIENTES!$B$25<>"",_PENDIENTES!$B$25,"") -> MARIA AUXILIADORA | N31: =IF(_PENDIENTES!$B$25<>"",_PENDIENTES!$L$25,"") -> MARIA AUXILIADORA
A32: =IF(_PENDIENTES!$B$26<>"",25,"") -> 25 | B32: =IF(_PENDIENTES!$B$26<>"",_PENDIENTES!$A$26,"") -> ENE | C32: =IF(_PENDIENTES!$B$26<>"",_PENDIENTES!$C$26,"") -> GOMEZ AQUINO CIELO IRAHY | D32: =IF(_PENDIENTES!$B$26<>"",_PENDIENTES!$D$26,"") -> 90953258 | E32: =IF(_PENDIENTES!$B$26<>"",_PENDIENTES!$E$26,"") -> 21/01/2026 | F32: =IF(_PENDIENTES!$B$26<>"",_PENDIENTES!$F$26,"") -> PETROLEO | G32: =IF(_PENDIENTES!$B$26<>"",_PENDIENTES!$G$26,"") -> 6.55 | H32: =IF(_PENDIENTES!$B$26<>"",_PENDIENTES!$H$26,"") -> 132.6375 | I32: =IF(_PENDIENTES!$B$26<>"",_PENDIENTES!$I$26,"") -> ROJAS ALVARADO BENJAMIN | J32: =IF(_PENDIENTES!$B$26<>"",_PENDIENTES!$J$26,"") -> 421 EUH | K32: =IF(_PENDIENTES!$B$26<>"","POR RECOGER","") -> POR RECOGER | L32: =IF(_PENDIENTES!$B$26<>"",_PENDIENTES!$K$26,"") -> 0 | M32: =IF(_PENDIENTES!$B$26<>"",_PENDIENTES!$B$26,"") -> MARIA AUXILIADORA | N32: =IF(_PENDIENTES!$B$26<>"",_PENDIENTES!$L$26,"") -> MARIA AUXILIADORA
A33: =IF(_PENDIENTES!$B$27<>"",26,"") -> 26 | B33: =IF(_PENDIENTES!$B$27<>"",_PENDIENTES!$A$27,"") -> ENE | C33: =IF(_PENDIENTES!$B$27<>"",_PENDIENTES!$C$27,"") -> ROJAS SANCHEZ TEODOLIO | D33: =IF(_PENDIENTES!$B$27<>"",_PENDIENTES!$D$27,"") -> 33415767 | E33: =IF(_PENDIENTES!$B$27<>"",_PENDIENTES!$E$27,"") -> 03/01/2026 | F33: =IF(_PENDIENTES!$B$27<>"",_PENDIENTES!$F$27,"") -> PETROLEO | G33: =IF(_PENDIENTES!$B$27<>"",_PENDIENTES!$G$27,"") -> 7 | H33: =IF(_PENDIENTES!$B$27<>"",_PENDIENTES!$H$27,"") -> 127.26 | I33: =IF(_PENDIENTES!$B$27<>"",_PENDIENTES!$I$27,"") -> LEIVA LARA JUNIOR | J33: =IF(_PENDIENTES!$B$27<>"",_PENDIENTES!$J$27,"") -> EUC 959 | K33: =IF(_PENDIENTES!$B$27<>"","POR RECOGER","") -> POR RECOGER | L33: =IF(_PENDIENTES!$B$27<>"",_PENDIENTES!$K$27,"") -> 0 | M33: =IF(_PENDIENTES!$B$27<>"",_PENDIENTES!$B$27,"") -> JALCA GRANDE | N33: =IF(_PENDIENTES!$B$27<>"",_PENDIENTES!$L$27,"") -> JALCA GRANDE
A34: =IF(_PENDIENTES!$B$28<>"",27,"") -> 27 | B34: =IF(_PENDIENTES!$B$28<>"",_PENDIENTES!$A$28,"") -> ENE | C34: =IF(_PENDIENTES!$B$28<>"",_PENDIENTES!$C$28,"") -> HUAMAN HUAMAN MARLENI | D34: =IF(_PENDIENTES!$B$28<>"",_PENDIENTES!$D$28,"") -> 43609007 | E34: =IF(_PENDIENTES!$B$28<>"",_PENDIENTES!$E$28,"") -> 19/01/2026 | F34: =IF(_PENDIENTES!$B$28<>"",_PENDIENTES!$F$28,"") -> PETROLEO | G34: =IF(_PENDIENTES!$B$28<>"",_PENDIENTES!$G$28,"") -> 7 | H34: =IF(_PENDIENTES!$B$28<>"",_PENDIENTES!$H$28,"") -> 127.26 | I34: =IF(_PENDIENTES!$B$28<>"",_PENDIENTES!$I$28,"") -> LEIVA LARA JUNIOR | J34: =IF(_PENDIENTES!$B$28<>"",_PENDIENTES!$J$28,"") -> EUC 959 | K34: =IF(_PENDIENTES!$B$28<>"","POR RECOGER","") -> POR RECOGER | L34: =IF(_PENDIENTES!$B$28<>"",_PENDIENTES!$K$28,"") -> 0 | M34: =IF(_PENDIENTES!$B$28<>"",_PENDIENTES!$B$28,"") -> JALCA GRANDE | N34: =IF(_PENDIENTES!$B$28<>"",_PENDIENTES!$L$28,"") -> JALCA GRANDE
A35: =IF(_PENDIENTES!$B$29<>"",28,"") -> 28 | B35: =IF(_PENDIENTES!$B$29<>"",_PENDIENTES!$A$29,"") -> ENE | C35: =IF(_PENDIENTES!$B$29<>"",_PENDIENTES!$C$29,"") -> ZAGACETA RAMOS NICOLAS MARTIN | D35: =IF(_PENDIENTES!$B$29<>"",_PENDIENTES!$D$29,"") -> 80812524 | E35: =IF(_PENDIENTES!$B$29<>"",_PENDIENTES!$E$29,"") -> 26/01/2025 | F35: =IF(_PENDIENTES!$B$29<>"",_PENDIENTES!$F$29,"") -> PETROLEO | G35: =IF(_PENDIENTES!$B$29<>"",_PENDIENTES!$G$29,"") -> 12 | H35: =IF(_PENDIENTES!$B$29<>"",_PENDIENTES!$H$29,"") -> 218.16 | I35: =IF(_PENDIENTES!$B$29<>"",_PENDIENTES!$I$29,"") -> MACHUCA GARRIDO RIDER ALFONSO | J35: =IF(_PENDIENTES!$B$29<>"",_PENDIENTES!$J$29,"") -> EUC 956 | K35: =IF(_PENDIENTES!$B$29<>"","POR RECOGER","") -> POR RECOGER | L35: =IF(_PENDIENTES!$B$29<>"",_PENDIENTES!$K$29,"") -> 0 | M35: =IF(_PENDIENTES!$B$29<>"",_PENDIENTES!$B$29,"") -> MARIA | N35: =IF(_PENDIENTES!$B$29<>"",_PENDIENTES!$L$29,"") -> MARIA
A36: =IF(_PENDIENTES!$B$30<>"",29,"") -> 29 | B36: =IF(_PENDIENTES!$B$30<>"",_PENDIENTES!$A$30,"") -> ENE | C36: =IF(_PENDIENTES!$B$30<>"",_PENDIENTES!$C$30,"") -> MAS MONTOYA ROSA VICTORIA | D36: =IF(_PENDIENTES!$B$30<>"",_PENDIENTES!$D$30,"") -> 33423243 | E36: =IF(_PENDIENTES!$B$30<>"",_PENDIENTES!$E$30,"") -> 03/01/2026 | F36: =IF(_PENDIENTES!$B$30<>"",_PENDIENTES!$F$30,"") -> GASOLINA | G36: =IF(_PENDIENTES!$B$30<>"",_PENDIENTES!$G$30,"") -> 8 | H36: =IF(_PENDIENTES!$B$30<>"",_PENDIENTES!$H$30,"") -> 143.6 | I36: =IF(_PENDIENTES!$B$30<>"",_PENDIENTES!$I$30,"") -> MAGNO CULQUIMBOS RUIZ | J36: =IF(_PENDIENTES!$B$30<>"",_PENDIENTES!$J$30,"") -> EUE-469 | K36: =IF(_PENDIENTES!$B$30<>"","POR RECOGER","") -> POR RECOGER | L36: =IF(_PENDIENTES!$B$30<>"",_PENDIENTES!$K$30,"") -> 0 | M36: =IF(_PENDIENTES!$B$30<>"",_PENDIENTES!$B$30,"") -> MOLINOPAMPA | N36: =IF(_PENDIENTES!$B$30<>"",_PENDIENTES!$L$30,"") -> MOLINOPAMPA
A37: =IF(_PENDIENTES!$B$31<>"",30,"") -> 30 | B37: =IF(_PENDIENTES!$B$31<>"",_PENDIENTES!$A$31,"") -> ENE | C37: =IF(_PENDIENTES!$B$31<>"",_PENDIENTES!$C$31,"") -> CANLLA GEBOL CELIDONIA | D37: =IF(_PENDIENTES!$B$31<>"",_PENDIENTES!$D$31,"") -> 48797632 | E37: =IF(_PENDIENTES!$B$31<>"",_PENDIENTES!$E$31,"") -> 07/01/2026 | F37: =IF(_PENDIENTES!$B$31<>"",_PENDIENTES!$F$31,"") -> GASOLINA | G37: =IF(_PENDIENTES!$B$31<>"",_PENDIENTES!$G$31,"") -> 8 | H37: =IF(_PENDIENTES!$B$31<>"",_PENDIENTES!$H$31,"") -> 143.6 | I37: =IF(_PENDIENTES!$B$31<>"",_PENDIENTES!$I$31,"") -> MAGNO CULQUIMBOS RUIZ | J37: =IF(_PENDIENTES!$B$31<>"",_PENDIENTES!$J$31,"") -> EUE-469 | K37: =IF(_PENDIENTES!$B$31<>"","POR RECOGER","") -> POR RECOGER | L37: =IF(_PENDIENTES!$B$31<>"",_PENDIENTES!$K$31,"") -> 0 | M37: =IF(_PENDIENTES!$B$31<>"",_PENDIENTES!$B$31,"") -> MOLINOPAMPA | N37: =IF(_PENDIENTES!$B$31<>"",_PENDIENTES!$L$31,"") -> MOLINOPAMPA
A38: =IF(_PENDIENTES!$B$32<>"",31,"") -> 31 | B38: =IF(_PENDIENTES!$B$32<>"",_PENDIENTES!$A$32,"") -> ENE | C38: =IF(_PENDIENTES!$B$32<>"",_PENDIENTES!$C$32,"") -> LOPEZ GUADALUPE NARDY FIORELA | D38: =IF(_PENDIENTES!$B$32<>"",_PENDIENTES!$D$32,"") -> 79521364 | E38: =IF(_PENDIENTES!$B$32<>"",_PENDIENTES!$E$32,"") -> 13/01/2026 | F38: =IF(_PENDIENTES!$B$32<>"",_PENDIENTES!$F$32,"") -> PETROLEO | G38: =IF(_PENDIENTES!$B$32<>"",_PENDIENTES!$G$32,"") -> 20 | H38: =IF(_PENDIENTES!$B$32<>"",_PENDIENTES!$H$32,"") -> 363.6 | I38: =IF(_PENDIENTES!$B$32<>"",_PENDIENTES!$I$32,"") -> SAUCEDO LOPEZ ELDIN NOLASCO | J38: =IF(_PENDIENTES!$B$32<>"",_PENDIENTES!$J$32,"") -> EUH699 | K38: =IF(_PENDIENTES!$B$32<>"","POR RECOGER","") -> POR RECOGER | L38: =IF(_PENDIENTES!$B$32<>"",_PENDIENTES!$K$32,"") -> 0 | M38: =IF(_PENDIENTES!$B$32<>"",_PENDIENTES!$B$32,"") -> COLLONCE | N38: =IF(_PENDIENTES!$B$32<>"",_PENDIENTES!$L$32,"") -> COLLONCE
A39: =IF(_PENDIENTES!$B$33<>"",32,"") -> 32 | B39: =IF(_PENDIENTES!$B$33<>"",_PENDIENTES!$A$33,"") -> ENE | C39: =IF(_PENDIENTES!$B$33<>"",_PENDIENTES!$C$33,"") -> ROJAS VARGAS MARIA CARMEN | D39: =IF(_PENDIENTES!$B$33<>"",_PENDIENTES!$D$33,"") -> 47181498 | E39: =IF(_PENDIENTES!$B$33<>"",_PENDIENTES!$E$33,"") -> 19/01/2026 | F39: =IF(_PENDIENTES!$B$33<>"",_PENDIENTES!$F$33,"") -> GASOLINA | G39: =IF(_PENDIENTES!$B$33<>"",_PENDIENTES!$G$33,"") -> 8 | H39: =IF(_PENDIENTES!$B$33<>"",_PENDIENTES!$H$33,"") -> 143.6 | I39: =IF(_PENDIENTES!$B$33<>"",_PENDIENTES!$I$33,"") -> MAGNO CULQUIMBOS RUIZ | J39: =IF(_PENDIENTES!$B$33<>"",_PENDIENTES!$J$33,"") -> EUE-469 | K39: =IF(_PENDIENTES!$B$33<>"","POR RECOGER","") -> POR RECOGER | L39: =IF(_PENDIENTES!$B$33<>"",_PENDIENTES!$K$33,"") -> 0 | M39: =IF(_PENDIENTES!$B$33<>"",_PENDIENTES!$B$33,"") -> MOLINOPAMPA | N39: =IF(_PENDIENTES!$B$33<>"",_PENDIENTES!$L$33,"") -> MOLINOPAMPA
A40: =IF(_PENDIENTES!$B$34<>"",33,"") -> 33 | B40: =IF(_PENDIENTES!$B$34<>"",_PENDIENTES!$A$34,"") -> ENE | C40: =IF(_PENDIENTES!$B$34<>"",_PENDIENTES!$C$34,"") -> IZQUERDO CORDOVA LUZ MERY | D40: =IF(_PENDIENTES!$B$34<>"",_PENDIENTES!$D$34,"") -> 46555340 | E40: =IF(_PENDIENTES!$B$34<>"",_PENDIENTES!$E$34,"") -> 20/01/2026 | F40: =IF(_PENDIENTES!$B$34<>"",_PENDIENTES!$F$34,"") -> PETROLEO | G40: =IF(_PENDIENTES!$B$34<>"",_PENDIENTES!$G$34,"") -> 20 | H40: =IF(_PENDIENTES!$B$34<>"",_PENDIENTES!$H$34,"") -> 363.6 | I40: =IF(_PENDIENTES!$B$34<>"",_PENDIENTES!$I$34,"") -> SAUCEDO LOPEZ ELDIN NOLASCO | J40: =IF(_PENDIENTES!$B$34<>"",_PENDIENTES!$J$34,"") -> EUH699 | K40: =IF(_PENDIENTES!$B$34<>"","POR RECOGER","") -> POR RECOGER | L40: =IF(_PENDIENTES!$B$34<>"",_PENDIENTES!$K$34,"") -> COLLONCE | M40: =IF(_PENDIENTES!$B$34<>"",_PENDIENTES!$B$34,"") -> COLLONCE | N40: =IF(_PENDIENTES!$B$34<>"",_PENDIENTES!$L$34,"") -> YAULICACHI
A41: =IF(_PENDIENTES!$B$35<>"",34,"") -> 34 | B41: =IF(_PENDIENTES!$B$35<>"",_PENDIENTES!$A$35,"") -> ENE | C41: =IF(_PENDIENTES!$B$35<>"",_PENDIENTES!$C$35,"") -> CHAVEZ LLANOS MILAGRO JHUDITH | D41: =IF(_PENDIENTES!$B$35<>"",_PENDIENTES!$D$35,"") -> 78374986 | E41: =IF(_PENDIENTES!$B$35<>"",_PENDIENTES!$E$35,"") -> 02/01/2026 | F41: =IF(_PENDIENTES!$B$35<>"",_PENDIENTES!$F$35,"") -> PETROLEO | G41: =IF(_PENDIENTES!$B$35<>"",_PENDIENTES!$G$35,"") -> 7.5 | H41: =IF(_PENDIENTES!$B$35<>"",_PENDIENTES!$H$35,"") -> 136.35 | I41: =IF(_PENDIENTES!$B$35<>"",_PENDIENTES!$I$35,"") -> CHAVEZ MORI DIMAS | J41: =IF(_PENDIENTES!$B$35<>"",_PENDIENTES!$J$35,"") -> EUH 636 | K41: =IF(_PENDIENTES!$B$35<>"","POR RECOGER","") -> POR RECOGER | L41: =IF(_PENDIENTES!$B$35<>"",_PENDIENTES!$K$35,"") -> 0 | M41: =IF(_PENDIENTES!$B$35<>"",_PENDIENTES!$B$35,"") -> LEYMEBAMBA | N41: =IF(_PENDIENTES!$B$35<>"",_PENDIENTES!$L$35,"") -> LEYMEBAMBA
A42: =IF(_PENDIENTES!$B$36<>"",35,"") -> 35 | B42: =IF(_PENDIENTES!$B$36<>"",_PENDIENTES!$A$36,"") -> ENE | C42: =IF(_PENDIENTES!$B$36<>"",_PENDIENTES!$C$36,"") -> ROJAS SILVA JOSE ALVINO | D42: =IF(_PENDIENTES!$B$36<>"",_PENDIENTES!$D$36,"") -> 33417523 | E42: =IF(_PENDIENTES!$B$36<>"",_PENDIENTES!$E$36,"") -> 09/01/2026 | F42: =IF(_PENDIENTES!$B$36<>"",_PENDIENTES!$F$36,"") -> PETROLEO | G42: =IF(_PENDIENTES!$B$36<>"",_PENDIENTES!$G$36,"") -> 6 | H42: =IF(_PENDIENTES!$B$36<>"",_PENDIENTES!$H$36,"") -> 109.08 | I42: =IF(_PENDIENTES!$B$36<>"",_PENDIENTES!$I$36,"") -> SALCEDO ZAGACETA FEDERICO | J42: =IF(_PENDIENTES!$B$36<>"",_PENDIENTES!$J$36,"") -> EUH-636 | K42: =IF(_PENDIENTES!$B$36<>"","POR RECOGER","") -> POR RECOGER | L42: =IF(_PENDIENTES!$B$36<>"",_PENDIENTES!$K$36,"") -> 0 | M42: =IF(_PENDIENTES!$B$36<>"",_PENDIENTES!$B$36,"") -> LEYMEBAMBA | N42: =IF(_PENDIENTES!$B$36<>"",_PENDIENTES!$L$36,"") -> LEYMEBAMBA
...

Sheet IPRESS
A1: CATALOGO DE IPRESS - UE 0725 (210 EESS)
A2: CODIGO RENAES | B2: NOMBRE IPRESS | C2: MICRORED
A3: 6754 | B3: 9 DE ENERO | C3: CHACHAPOYAS
A4: 6990 | B4: ACHAMAL | C4: TOTORA
A5: 7172 | B5: AGUA SANTA | C5: SANTO TOMAS
A6: 4912 | B6: ASUNCION GONCHA | C6: JUMBILLA
A7: 7175 | B7: ATUEN | C7: LEIMEBAMBA
A8: 27354 | B8: AYLLU SACHAPUYOS | C8: AYLLU SACHAPUYOS
A9: 7206 | B9: BALERIANA | C9: MARIA
A10: 4856 | B10: BALZAS | C10: LEIMEBAMBA
A11: 7334 | B11: BUENA VISTA | C11: MARIA
A12: 4937 | B12: BUENOS AIRES | C12: POMACOCHAS
A13: 7070 | B13: BUIQUIL | C13: YERBABUENA
... A212: 4954 | B212: ZARUMILLA | C212: ZARUMILLA

Sheet ENERO 2025
A1: REPORTE DE TRASLADO DE PACIENTES SIS DEL MES DE ENERO 2025 PARA REPOSICION DE COMBUSTIBLE
A2: TOTAL PETROLEO (gal): | D2: =IFERROR(SUMPRODUCT((K4:K113="PETROLEO")*ISNUMBER(M4:M113)*M4:M113),0) -> 0 | G2: TOTAL GASOLINA (gal): | J2: =IFERROR(SUMPRODUCT((K4:K113="GASOLINA")*ISNUMBER(M4:M113)*M4:M113),0) -> 0 | M2: TOTAL SOLES S/.: | P2: =IFERROR(SUMPRODUCT(ISNUMBER(M4:M113)*L4:L113*M4:M113),0) -> 0 | S2: N TRASLADOS: | U2: =SUBTOTAL(2,A4:A113) -> 106 | W2: ↑ Al filtrar por EESS los totales cambian automáticamente
Y3: DEVOLVER A (IPRESS DESTINO)
A4: COLUMNAS EN AZUL = AUTO (no editar) | Ingrese: N, NRO FORMATO, AFILIADO, TIPO DOC, NRO DOC, FECHA TRASLADO, COD RENAES, COD REFERENCIA, DNI CONDUCTOR, PRECIO GAL, GALONES, FECHA ENTREGA, CIE-10, ESTADO FUA, FECHA DIGITACION, OFICIO, O/C, META, OBSERVACION
A5: N | B5: NRO FORMATO ATENCION | C5: UNIDAD EJECUTORA | D5: AFILIADO | E5: TIPO DOC | F5: NRO DOCUMENTO | G5: FECHA TRASLADO | H5: COD RENAES | I5: DESCRIPCION EESS | J5: COD EESS REFERENCIA | K5: TIPO DE COMBUSTIBLE | L5: PRECIO GAL S/. | M5: GALONES | N5: TOTAL COMBUSTIBLE S/. | O5: DNI CONDUCTOR | P5: =IFERROR(VLOOKUP(TEXT(O5,"0"),CONDUCTORES!$A$3:$G$100,2,0),"") | Q5: =IFERROR(VLOOKUP(TEXT(O5,"0"),CONDUCTORES!$A$3:$H$100,6,0),"") | R5: FECHA DE ENTREGA | S5: CODIGO DE DIAGNOSTICO | T5: ESTADO FUA | U5: FECHA DIGITACION | V5: OFICIO | W5: O/C | X5: META | Y5: OBSERVACION
A6: 1 | B6: 00090006 | C6: REGION | D6: FUANTES LOPEZ ANYELI GABRIELA | E6: DNI | F6: 63391895 | G6: 45675 | H6: 4954 | I6: =IFERROR(VLOOKUP(TEXT(H6,"0"),IPRESS!$A$3:$B$212,2,0),"") -> ZARUMILLA | J6: 4838 | K6: =IFERROR(VLOOKUP(TEXT(O6,"0"),CONDUCTORES!$A$3:$G$100,7,0),"") | L6: 20.25 | M6: 6 | N6: =IFERROR(IF(L6*M6=0,"",L6*M6),"") -> 121.5 | P6: =IFERROR(VLOOKUP(TEXT(O6,"0"),CONDUCTORES!$A$3:$G$100,2,0),"") | Q6: =IFERROR(VLOOKUP(TEXT(O6,"0"),CONDUCTORES!$A$3:$H$100,6,0),"") | R6: ATENDIDO 01/07/2025 | S6: R100-K802 | T6: APROBADO | U6: 45698 | V6: 3041-2025 | W6: 3479.0 | X6: 189.0
A7: 2 | B7: 00090007 | C7: REGION | D7: BURGA BACA MARLITH | E7: DNI | F7: 77063161 | G7: 45680 | H7: 4954 | I7: =IFERROR(VLOOKUP(TEXT(H7,"0"),IPRESS!$A$3:$B$212,2,0),"") -> ZARUMILLA | J7: 4950 | K7: =IFERROR(VLOOKUP(TEXT(O7,"0"),CONDUCTORES!$A$3:$G$100,7,0),"") | L7: 20.25 | M7: 6 | N7: =IFERROR(IF(L7*M7=0,"",L7*M7),"") -> 121.5 | P7: =IFERROR(VLOOKUP(TEXT(O7,"0"),CONDUCTORES!$A$3:$G$100,2,0),"") | Q7: =IFERROR(VLOOKUP(TEXT(O7,"0"),CONDUCTORES!$A$3:$H$100,6,0),"") | R7: ATENDIDO 01/07/2025 | S7: O603 | T7: APROBADO | U7: 45698 | V7: 3041-2025 | W7: 3479.0 | X7: 189.0
A8: 3 | B8: 000000010 | C8: REGION | D8: ARRUE IBERICO JUAN FRANCISCO | E8: DNI | F8: 48008043 | G8: 45688 | H8: 4954 | I8: =IFERROR(VLOOKUP(TEXT(H8,"0"),IPRESS!$A$3:$B$212,2,0),"") -> ZARUMILLA | J8: 4950 | K8: =IFERROR(VLOOKUP(TEXT(O8,"0"),CONDUCTORES!$A$3:$G$100,7,0),"") | L8: 20.25 | M8: 6 | N8: =IFERROR(IF(L8*M8=0,"",L8*M8),"") -> 121.5 | P8: =IFERROR(VLOOKUP(TEXT(O8,"0"),CONDUCTORES!$A$3:$G$100,2,0),"") | Q8: =IFERROR(VLOOKUP(TEXT(O8,"0"),CONDUCTORES!$A$3:$H$100,6,0),"") | R8: ATENDIDO 01/07/2025 | S8: F99X,F209 | U8: 45709 | V8: 3041-2025 | W8: 3479.0 | X8: 189.0
A9: 4 | B9: 000000008 | C9: REGION | D9: RIVA TRIGOSO SEGUNDO GUILLERMO | E9: DNI | F9: 33950725 | G9: 45685 | H9: 4954 | I9: =IFERROR(VLOOKUP(TEXT(H9,"0"),IPRESS!$A$3:$B$212,2,0),"") -> ZARUMILLA | J9: 4950 | K9: =IFERROR(VLOOKUP(TEXT(O9,"0"),CONDUCTORES!$A$3:$G$100,7,0),"") | L9: 20.25 | M9: 6 | N9: =IFERROR(IF(L9*M9=0,"",L9*M9),"") -> 121.5 | P9: =IFERROR(VLOOKUP(TEXT(O9,"0"),CONDUCTORES!$A$3:$G$100,2,0),"") | Q9: =IFERROR(VLOOKUP(TEXT(O9,"0"),CONDUCTORES!$A$3:$H$100,6,0),"") | R9: ATENDIDO 01/07/2025 | S9: S223,I939 | U9: 45721 | V9: 3041-2025 | W9: 3479.0 | X9: 189.0
A10: 5 | B10: 000000002 | C10: REGION | D10: TAFUR TRUJILLO ESTER | E10: DNI | F10: 80695099 | G10: 45687 | H10: 4888 | I10: =IFERROR(VLOOKUP(TEXT(H10,"0"),IPRESS!$A$3:$B$212,2,0),"") -> SAN SALVADOR | J10: 4838 | K10: =IFERROR(VLOOKUP(TEXT(O10,"0"),CONDUCTORES!$A$3:$G$100,7,0),"") | L10: 18.18 | M10: 10 | N10: =IFERROR(IF(L10*M10=0,"",L10*M10),"") -> 181.8 | P10: =IFERROR(VLOOKUP(TEXT(O10,"0"),CONDUCTORES!$A$3:$G$100,2,0),"") | Q10: =IFERROR(VLOOKUP(TEXT(O10,"0"),CONDUCTORES!$A$3:$H$100,6,0),"") | R10: ATENDIDO 09/10/2025 | S10: A059,T784 | U10: 45721
A11: 6 | B11: 000000003 | C11: REGION | D11: VALLE CHAVEZ ROMINA MIRSEL | E11: DNI | F11: 60229576 | G11: 45677 | H11: 4895 | I11: =IFERROR(VLOOKUP(TEXT(H11,"0"),IPRESS!$A$3:$B$212,2,0),"") -> COLCAMAR | J11: 4838 | K11: =IFERROR(VLOOKUP(TEXT(O11,"0"),CONDUCTORES!$A$3:$G$100,7,0),"") | L11: 18.18 | M11: 8 | N11: =IFERROR(IF(L11*M11=0,"",L11*M11),"") -> 145.44 | P11: =IFERROR(VLOOKUP(TEXT(O11,"0"),CONDUCTORES!$A$3:$G$100,2,0),"") | Q11: =IFERROR(VLOOKUP(TEXT(O11,"0"),CONDUCTORES!$A$3:$H$100,6,0),"") | R11: ATENDIDIO 20/06/2025 | S11: O300 | U11: 45721 | V11: 2888-2025 | W11: CONTRATO N° 001-2025 DYT | X11: 267.0
A12: 7 | B12: 00000001 | C12: REGION | D12: FUENTES COLVAQUE ELIZABETH | E12: DNI | F12: 74858351 | G12: 45678 | H12: 4873 | I12: =IFERROR(VLOOKUP(TEXT(H12,"0"),IPRESS!$A$3:$B$212,2,0),"") -> CAMPORREDONDO | J12: 4838 | K12: =IFERROR(VLOOKUP(TEXT(O12,"0"),CONDUCTORES!$A$3:$G$100,7,0),"") | L12: 18.18 | M12: 20 | N12: =IFERROR(IF(L12*M12=0,"",L12*M12),"") -> 363.6 | P12: =IFERROR(VLOOKUP(TEXT(O12,"0"),CONDUCTORES!$A$3:$G$100,2,0),"") | Q12: =IFERROR(VLOOKUP(TEXT(O12,"0"),CONDUCTORES!$A$3:$H$100,6,0),"") | R12: ATENDIDO 03-04-2025 | S12: O603,O429 | U12: 45705 | V12: 0000108-ADENDA N° 001-2025DRSA/OEA.OABAST | W12: 2025.0 | X12: 256.0
A13: 8 | B13: 000000009 | C13: REGION | D13: LOJA MORI CECILIA MARGUIT | E13: DNI | F13: 73375465 | G13: 45672 | H13: 4887 | I13: =IFERROR(VLOOKUP(TEXT(H13,"0"),IPRESS!$A$3:$B$212,2,0),"") -> SANTO TOMAS | J13: 4838 | K13: =IFERROR(VLOOKUP(TEXT(O13,"0"),CONDUCTORES!$A$3:$G$100,7,0),"") | L13: 18.18 | M13: 10 | N13: =IFERROR(IF(L13*M13=0,"",L13*M13),"") -> 181.8 | P13: =IFERROR(VLOOKUP(TEXT(O13,"0"),CONDUCTORES!$A$3:$G$100,2,0),"") | Q13: =IFERROR(VLOOKUP(TEXT(O13,"0"),CONDUCTORES!$A$3:$H$100,6,0),"") | R13: ATENDIDO 12/05/2025 | S13: Z359-O629 | T13: APROBADO | U13: 45691 | V13: OFICO 1937-2025 | W13: 0000108- ADENDA N°001-2025 DRSA/OEA-O.ABAST | X13: 256.0
A14: 9 | B14: 000000007 | C14: REGION | D14: TAFUR BAZAN EMELY ALEXANDRA | E14: DNI | F14: 94059688 | G14: 45675 | H14: 4887 | I14: =IFERROR(VLOOKUP(TEXT(H14,"0"),IPRESS!$A$3:$B$212,2,0),"") -> SANTO TOMAS | J14: 4838 | K14: =IFERROR(VLOOKUP(TEXT(O14,"0"),CONDUCTORES!$A$3:$G$100,7,0),"") | L14: 18.18 | M14: 10 | N14: =IFERROR(IF(L14*M14=0,"",L14*M14),"") -> 181.8 | P14: =IFERROR(VLOOKUP(TEXT(O14,"0"),CONDUCTORES!$A$3:$G$100,2,0),"") | Q14: =IFERROR(VLOOKUP(TEXT(O14,"0"),CONDUCTORES!$A$3:$H$100,6,0),"") | R14: ATENDIDO 12/05/2025 | S14: R17X-A419 | T14: APROBADO | U14: 45692 | V14: OFICO 1937-2025 | W14: 0000108- ADENDA N°001-2025 DRSA/OEA-O.ABAST | X14: 256.0
A15: 10 | B15: 000000008 | C15: REGION | D15: VALQUI DE BUSTAMANTE MARIA DIONICIA | E15: DNI | F15: 33806181 | G15: 45684 | H15: 4887 | I15: =IFERROR(VLOOKUP(TEXT(H15,"0"),IPRESS!$A$3:$B$212,2,0),"") -> SANTO TOMAS | J15: 4838 | K15: =IFERROR(VLOOKUP(TEXT(O15,"0"),CONDUCTORES!$A$3:$G$100,7,0),"") | L15: 18.18 | M15: 10 | N15: =IFERROR(IF(L15*M15=0,"",L15*M15),"") -> 181.8 | P15: =IFERROR(VLOOKUP(TEXT(O15,"0"),CONDUCTORES!$A$3:$G$100,2,0),"") | Q15: =IFERROR(VLOOKUP(TEXT(O15,"0"),CONDUCTORES!$A$3:$H$100,6,0),"") | R15: ATENDIDO 12/05/2025 | S15: K819-R101 | T15: APROBADO | U15: 45705 | V15: OFICO 1937-2025 | W15: 0000108- ADENDA N°001-2025 DRSA/OEA-O.ABAST | X15: 256.0
A16: 11 | B16: 00000001 | C16: REGION | D16: CHUQUIPIONDO GUAMAN YBARISTA | E16: DNI | F16: 45148187 | G16: 45680 | H16: 4895 | I16: =IFERROR(VLOOKUP(TEXT(H16,"0"),IPRESS!$A$3:$B$212,2,0),"") -> COLCAMAR | J16: 4838 | K16: =IFERROR(VLOOKUP(TEXT(O16,"0"),CONDUCTORES!$A$3:$G$100,7,0),"") | L16: 18.18 | M16: 8 | N16: =IFERROR(IF(L16*M16=0,"",L16*M16),"") -> 145.44 | P16: =IFERROR(VLOOKUP(TEXT(O16,"0"),CONDUCTORES!$A$3:$G$100,2,0),"") | Q16: =IFERROR(VLOOKUP(TEXT(O16,"0"),CONDUCTORES!$A$3:$H$100,6,0),"") | R16: ATENDIDO 13/05/2025 | S16: K828 | T16: APROBADO | U16: 45705
A17: 12 | B17: 000000002 | C17: REGION | D17: BARDALES CHUQUIPA JOSE | E17: DNI | F17: 33422417 | G17: 45674 | H17: 4869 | I17: =IFERROR(VLOOKUP(TEXT(H17,"0"),IPRESS!$A$3:$B$212,2,0),"") -> MOLINOPAMPA | J17: 4838 | K17: =IFERROR(VLOOKUP(TEXT(O17,"0"),CONDUCTORES!$A$3:$G$100,7,0),"") | L17: 17.95 | M17: 8 | N17: =IFERROR(IF(L17*M17=0,"",L17*M17),"") -> 143.6 | P17: =IFERROR(VLOOKUP(TEXT(O17,"0"),CONDUCTORES!$A$3:$G$100,2,0),"") | Q17: =IFERROR(VLOOKUP(TEXT(O17,"0"),CONDUCTORES!$A$3:$H$100,6,0),"") | R17: ATENDIDO 13/05/2025 | S17: K922 | T17: APROBADO | U17: 45691 | V17: OFICIO 1940-2025 | W17: 0000108- ADENDA N°001-2025 DRSA/OEA-O.ABAST | X17: 257.0
A18: 13 | B18: 00000003 | C18: REGION | D18: MONTOYA SOPLA FRANCISCO | E18: DNI | F18: 33422421 | G18: 45676 | H18: 4869 | I18: =IFERROR(VLOOKUP(TEXT(H18,"0"),IPRESS!$A$3:$B$212,2,0),"") -> MOLINOPAMPA | J18: 4838 | K18: =IFERROR(VLOOKUP(TEXT(O18,"0"),CONDUCTORES!$A$3:$G$100,7,0),"") | L18: 17.95 | M18: 8 | N18: =IFERROR(IF(L18*M18=0,"",L18*M18),"") -> 143.6 | P18: =IFERROR(VLOOKUP(TEXT(O18,"0"),CONDUCTORES!$A$3:$G$100,2,0),"") | Q18: =IFERROR(VLOOKUP(TEXT(O18,"0"),CONDUCTORES!$A$3:$H$100,6,0),"") | R18: ATENDIDO 13/05/2025 | S18: J189-J969 | T18: APROBADO | U18: 45698 | V18: OFICIO 1940-2025 | W18: 0000108- ADENDA N°001-2025 DRSA/OEA-O.ABAST | X18: 257.0
A19: 14 | B19: 000000004 | C19: REGION | D19: SOPLA CULQUI HOMERO | E19: DNI | F19: 33426435 | G19: 45684 | H19: 4689 | I19: =IFERROR(VLOOKUP(TEXT(H19,"0"),IPRESS!$A$3:$B$212,2,0),"") | J19: 4838 | K19: =IFERROR(VLOOKUP(TEXT(O19,"0"),CONDUCTORES!$A$3:$G$100,7,0),"") | L19: 17.95 | M19: 8 | N19: =IFERROR(IF(L19*M19=0,"",L19*M19),"") -> 143.6 | P19: =IFERROR(VLOOKUP(TEXT(O19,"0"),CONDUCTORES!$A$3:$G$100,2,0),"") | Q19: =IFERROR(VLOOKUP(TEXT(O19,"0"),CONDUCTORES!$A$3:$H$100,6,0),"") | R19: ATENDIDO 13/05/2025 | S19: S029-S099 | T19: APROBADO | U19: 45705 | V19: OFICIO 1940-2025 | W19: 0000108- ADENDA N°001-2025 DRSA/OEA-O.ABAST | X19: 257.0
A20: 15 | B20: 00000005 | C20: REGION | D20: CADENILLAS ALTAMIRANO LUZ MARITHA | E20: DNI | F20: 48683561 | G20: 45677 | H20: 4932 | I20: =IFERROR(VLOOKUP(TEXT(H20,"0"),IPRESS!$A$3:$B$212,2,0),"") -> POMACOCHAS | J20: 4838 | K20: =IFERROR(VLOOKUP(TEXT(O20,"0"),CONDUCTORES!$A$3:$G$100,7,0),"") | L20: 18.18 | M20: 8 | N20: =IFERROR(IF(L20*M20=0,"",L20*M20),"") -> 145.44 | P20: =IFERROR(VLOOKUP(TEXT(O20,"0"),CONDUCTORES!$A$3:$G$100,2,0),"") | Q20: =IFERROR(VLOOKUP(TEXT(O20,"0"),CONDUCTORES!$A$3:$H$100,6,0),"") | R20: ATENDIDO 13/05/2025 | S20: Z359-O639-O234 | T20: APROBADO | U20: 45698 | V20: OFICIO 1957-2025 | W20: 0000108- ADENDA N°001-2025 DRSA/OEA-O.ABAST | X20: 256.0
